<?xml version="1.0" ?>
<!-- =================================================================================== -->
<!-- |    This document was autogenerated by xacro from src/anytwin_urdf_development/urdf/anytwin_c.urdf.xacro | -->
<!-- |    EDITING THIS FILE BY HAND IS NOT RECOMMENDED                                 | -->
<!-- =================================================================================== -->
<robot name="anytwins">
  <link name="base_link">
    <visual>
      <origin rpy="0 1.57079633 0" xyz="0 0 0"/>
      <geometry>
        <cylinder length="1.2" radius="0.05"/>
      </geometry>
    </visual>
  </link>
  <!--left joint and connection-->
  <link name="left_connector">
    <visual>
      <origin xyz="0 0 -0.15"/>
      <geometry>
        <cylinder length="0.3" radius="0.05"/>
      </geometry>
    </visual>
  </link>
  <link name="left_joint_body">
    <visual>
      <origin xyz="0 0 0"/>
      <geometry>
        <sphere radius="0.07"/>
      </geometry>
    </visual>
  </link>
  <joint name="left_joint_roll" type="fixed">
    <parent link="base_link"/>
    <child link="left_joint_body"/>
    <origin xyz="0.6 0 0"/>
  </joint>
  <joint name="left_joint_yaw" type="fixed">
    <parent link="left_joint_body"/>
    <child link="left_connector"/>
    <origin xyz="0 0 0"/>
  </joint>
  <!--right joint and connection-->
  <link name="right_connector">
    <visual>
      <origin xyz="0 0 -0.15"/>
      <geometry>
        <cylinder length="0.3" radius="0.05"/>
      </geometry>
    </visual>
  </link>
  <link name="right_joint_body">
    <visual>
      <origin xyz="0 0 0"/>
      <geometry>
        <sphere radius="0.07"/>
      </geometry>
    </visual>
  </link>
  <joint name="right_joint_roll" type="fixed">
    <parent link="base_link"/>
    <child link="right_joint_body"/>
    <origin xyz="-0.6 0 0"/>
  </joint>
  <joint name="right_joint_yaw" type="fixed">
    <parent link="right_joint_body"/>
    <child link="right_connector"/>
    <origin xyz="0 0 0"/>
  </joint>
  <gazebo>
    <plugin filename="libanymal_gazebo.so" name="gazebo_ros_control">
      <robotNamespace>anymal</robotNamespace>
      <!-- Currently unused -->
      <robotDescription>anymal_description</robotDescription>
      <robotBaseLink>base</robotBaseLink>
    </plugin>
  </gazebo>
  <!-- [kg * m^2] -->
  <!-- [m] -->
  <!-- measured -->
  <!-- Base link -->
  <link name="base_B">
    <visual>
      <origin rpy="0 0 0" xyz="0 0 0"/>
      <geometry>
        <mesh filename="../meshes/base_3_1_1_mesh.dae" scale="1.0 1.0     1.0"/>
      </geometry>
    </visual>
    <collision>
      <origin rpy="0 0 0" xyz="0 0 0"/>
      <geometry>
        <box size="0.58 0.14 0.18"/>
      </geometry>
    </collision>
    <collision>
      <origin rpy="0 1.5707963267948966 0" xyz="0.21749999999999997 0.07 0"/>
      <geometry>
        <cylinder length="0.145" radius="0.09"/>
      </geometry>
    </collision>
    <collision>
      <origin rpy="0 1.5707963267948966 0" xyz="-0.21749999999999997 0.07 0"/>
      <geometry>
        <cylinder length="0.145" radius="0.09"/>
      </geometry>
    </collision>
    <collision>
      <origin rpy="0 1.5707963267948966 0" xyz="0.21749999999999997 -0.07 0"/>
      <geometry>
        <cylinder length="0.145" radius="0.09"/>
      </geometry>
    </collision>
    <collision>
      <origin rpy="0 1.5707963267948966 0" xyz="-0.21749999999999997 -0.07 0"/>
      <geometry>
        <cylinder length="0.145" radius="0.09"/>
      </geometry>
    </collision>
    <!-- Shell self filtering -->
    <self_filter>
      <origin rpy="0 0 0" xyz="0 0 0"/>
      <geometry>
        <box size="1.05 0.5 0.5"/>
      </geometry>
    </self_filter>
  </link>
  <!-- Fixed joint to add dummy inertia link -->
  <joint name="base_to_base_inertia_B" type="fixed">
    <parent link="base_B"/>
    <child link="base_inertia_B"/>
    <origin rpy="0 0 0" xyz="0 0 0"/>
  </joint>
  <!-- Dummy inertia link, because KDL cannot have inertia on the base link -->
  <link name="base_inertia_B">
    <inertial>
      <origin rpy="0 0 0" xyz="-0.018 -0.002 0.024"/>
      <mass value="6.222"/>
      <inertia ixx="0.017938806" ixy="0.00387963" ixz="0.001500772" iyy="0.370887745" iyz="6.8963e-05" izz="0.372497653"/>
    </inertial>
  </link>
  <!-- [kg * m^2] -->
  <!-- Fixed joint base topshell -->
  <joint name="base_top_shell_B" type="fixed">
    <parent link="base_B"/>
    <child link="top_shell_B"/>
    <origin rpy="0 0 0" xyz="0 0 0"/>
  </joint>
  <!-- Top shell link -->
  <link name="top_shell_B">
    <visual>
      <origin rpy="0 0 0" xyz="0 0 0"/>
      <geometry>
        <mesh filename="../meshes/top_shell_3_1_1_mesh.dae" scale="1.0 1.0 1.0"/>
      </geometry>
    </visual>
    <inertial>
      <origin rpy="0 0 0" xyz="-0.00777 -0.00013 0.06523"/>
      <mass value="0.534"/>
      <inertia ixx="0.00664789486" ixy="1.247923e-05" ixz="0.00053990097" iyy="0.02587392411" iyz="3.7614e-07" izz="0.03152303792"/>
    </inertial>
  </link>
  <!-- [kg * m^2] -->
  <!-- Fixed joint base topshell -->
  <joint name="base_bottom_shell_B" type="fixed">
    <parent link="base_B"/>
    <child link="bottom_shell_B"/>
    <origin rpy="0 0 0" xyz="0 0 0"/>
  </joint>
  <!-- Bottom shell link -->
  <link name="bottom_shell_B">
    <visual>
      <origin rpy="0 0 0" xyz="0 0 0"/>
      <geometry>
        <mesh filename="../meshes/bottom_shell_3_1_1_mesh.dae" scale="1.0 1.0 1.0"/>
      </geometry>
    </visual>
    <inertial>
      <origin rpy="0 0 0" xyz="-0.00333 1e-05 -0.07705"/>
      <mass value="1.15"/>
      <inertia ixx="0.00927353677" ixy="5.41222e-06" ixz="9.039821e-05" iyy="0.06134388239" iyz="2.3042e-07" izz="0.06853531465"/>
    </inertial>
  </link>
  <!-- [kg * m^2] -->
  <!-- Fixed joint base remote -->
  <joint name="base_remote_B" type="fixed">
    <parent link="base_B"/>
    <child link="remote_B"/>
    <origin rpy="0 0 0" xyz="0 0 0"/>
  </joint>
  <!-- Remote link -->
  <link name="remote_B">
    <visual>
      <origin rpy="0 0 0" xyz="0 0 0"/>
      <geometry>
        <mesh filename="../meshes/remote_3_1_1_mesh.dae" scale="1.0 1.0     1.0"/>
      </geometry>
    </visual>
    <inertial>
      <origin rpy="0 0 0" xyz="-0.171 0.002 0.096"/>
      <mass value="0.3262"/>
      <inertia ixx="0.000528486" ixy="4.547e-05" ixz="1.10327e-05" iyy="0.001165035" iyz="7.4e-07" izz="0.00124026"/>
    </inertial>
  </link>
  <!-- [kg * m^2] -->
  <!-- Fixed joint base handle -->
  <joint name="base_handle_B" type="fixed">
    <parent link="base_B"/>
    <child link="handle_B"/>
    <origin rpy="0 0 0" xyz="0 0 0"/>
  </joint>
  <!-- Handle link -->
  <link name="handle_B">
    <visual>
      <origin rpy="0 0 0" xyz="0 0 0"/>
      <geometry>
        <mesh filename="../meshes/handle_3_1_1_mesh.dae" scale="1.0 1.0     1.0"/>
      </geometry>
    </visual>
    <inertial>
      <origin rpy="0 0 0" xyz="0.37801 0.0 0.1372"/>
      <mass value="0.314"/>
      <inertia ixx="0.001525739" ixy="0.0" ixz="6.272e-05" iyy="0.00071584" iyz="1e-09" izz="0.001164779"/>
    </inertial>
  </link>
  <!-- [m] -->
  <!-- measured -->
  <!-- Fixed joint base face -->
  <joint name="base_face_front_B" type="fixed">
    <parent link="base_B"/>
    <child link="face_front_B"/>
    <origin rpy="0 0 -0.0" xyz="0.4145 0 0"/>
  </joint>
  <!-- Shell link -->
  <link name="face_front_B">
    <visual>
      <origin rpy="0 0 0" xyz="0 0 0"/>
      <geometry>
        <mesh filename="../meshes/face_3_1_1_mesh.dae" scale="1.0 1.0 1.0"/>
      </geometry>
    </visual>
    <collision>
      <origin rpy="0 0 0" xyz="0.055 0 0"/>
      <geometry>
        <box size="0.11 0.14 0.18"/>
      </geometry>
    </collision>
    <collision>
      <origin rpy="0 1.5707963267948966 0" xyz="0.055 0.07 0"/>
      <geometry>
        <cylinder length="0.11" radius="0.09"/>
      </geometry>
    </collision>
    <collision>
      <origin rpy="0 1.5707963267948966 0" xyz="0.055 -0.07 0"/>
      <geometry>
        <cylinder length="0.11" radius="0.09"/>
      </geometry>
    </collision>
    <inertial>
      <origin rpy="0 0 0" xyz="0.042 -0.001 0.004"/>
      <mass value="0.73"/>
      <inertia ixx="0.005238611" ixy="1.7609e-05" ixz="7.2167e-05" iyy="0.002643098" iyz="1.9548e-05" izz="0.004325938"/>
    </inertial>
  </link>
  <!-- [kg * m^2] -->
  <!-- [m] -->
  <!-- Camera joint -->
  <!-- Is located between the two back screw holes at ground level. -->
  <joint name="face_front_B_to_depth_camera_front_B_camera" type="fixed">
    <parent link="face_front_B"/>
    <child link="depth_camera_front_B_camera"/>
    <origin rpy="0.0 0.5235987755982988 0" xyz="0.04715 0.0 -0.0292"/>
  </joint>
  <!-- Camera link -->
  <link name="depth_camera_front_B_camera">
    <visual>
      <origin rpy="0 0 0" xyz="0.0 0.0 0.0"/>
      <geometry>
        <mesh filename="../meshes/realsense_d435_3_1_1_mesh.dae" scale="1.0 1.0 1.0"/>
      </geometry>
    </visual>
    <inertial>
      <origin rpy="0 0 0" xyz="-0.021 -0.002 0.025"/>
      <mass value="0.16043"/>
      <inertia ixx="0.000637051" ixy="0.000484569" ixz="0.000424211" iyy="0.000929402" iyz="5.138e-06" izz="0.000484569"/>
    </inertial>
  </link>
  <!-- Camera parent joint -->
  <!-- Frame lies on the left ir camera according to any_realsense2_camera urdf. -->
  <joint name="depth_camera_front_B_camera_to_camera_parent" type="fixed">
    <parent link="depth_camera_front_B_camera"/>
    <child link="depth_camera_front_B_camera_parent"/>
    <origin rpy="0.0 0.0 0.0" xyz="0.0255 0.0175 0.0"/>
  </joint>
  <!-- Camera parent link -->
  <link name="depth_camera_front_B_camera_parent"/>
  <!-- simulation or bagfile_is_played -->
  <!-- simulation -->
  <!-- [kg * m^2] -->
  <!-- [m] -->
  <!-- Camera joint -->
  <!-- Is located in the center of the mounting points. -->
  <joint name="face_front_B_to_wide_angle_camera_front_B_camera" type="fixed">
    <parent link="face_front_B"/>
    <child link="wide_angle_camera_front_B_camera"/>
    <origin rpy="0 0 0" xyz="0.09850 0.0 0.01497"/>
  </joint>
  <!-- Camera link -->
  <link name="wide_angle_camera_front_B_camera">
    <visual>
      <origin rpy="0 0 0" xyz="0.0 0.0 0.0"/>
      <geometry>
        <mesh filename="../meshes/blackfly_3_1_1_mesh.dae" scale="1.0 1.0 1.0"/>
      </geometry>
    </visual>
    <inertial>
      <origin rpy="0 0 0" xyz="-0.053 -0.001 0.025"/>
      <mass value="0.287"/>
      <inertia ixx="0.000559232" ixy="1.6875e-05" ixz="0.000423761" iyy="0.000946504" iyz="1.3234e-07" izz="0.000493052"/>
    </inertial>
  </link>
  <!-- Camera parent joint -->
  <joint name="wide_angle_camera_front_B_camera_to_camera_parent" type="fixed">
    <parent link="wide_angle_camera_front_B_camera"/>
    <child link="wide_angle_camera_front_B_camera_parent"/>
    <origin rpy="-1.5707963267948966 0.0 -1.5707963267948966" xyz="0.0 0.0 0.0"/>
  </joint>
  <!-- Camera parent link -->
  <link name="wide_angle_camera_front_B_camera_parent"/>
  <!-- simulation -->
  <!-- [m] -->
  <!-- measured -->
  <!-- Fixed joint base face -->
  <joint name="base_face_rear_B" type="fixed">
    <parent link="base_B"/>
    <child link="face_rear_B"/>
    <origin rpy="0 0 3.141592653589793" xyz="-0.4145 0 0"/>
  </joint>
  <!-- Shell link -->
  <link name="face_rear_B">
    <visual>
      <origin rpy="0 0 0" xyz="0 0 0"/>
      <geometry>
        <mesh filename="../meshes/face_3_1_1_mesh.dae" scale="1.0 1.0 1.0"/>
      </geometry>
    </visual>
    <collision>
      <origin rpy="0 0 0" xyz="0.055 0 0"/>
      <geometry>
        <box size="0.11 0.14 0.18"/>
      </geometry>
    </collision>
    <collision>
      <origin rpy="0 1.5707963267948966 0" xyz="0.055 0.07 0"/>
      <geometry>
        <cylinder length="0.11" radius="0.09"/>
      </geometry>
    </collision>
    <collision>
      <origin rpy="0 1.5707963267948966 0" xyz="0.055 -0.07 0"/>
      <geometry>
        <cylinder length="0.11" radius="0.09"/>
      </geometry>
    </collision>
    <inertial>
      <origin rpy="0 0 0" xyz="0.042 -0.001 0.004"/>
      <mass value="0.73"/>
      <inertia ixx="0.005238611" ixy="1.7609e-05" ixz="7.2167e-05" iyy="0.002643098" iyz="1.9548e-05" izz="0.004325938"/>
    </inertial>
  </link>
  <!-- [kg * m^2] -->
  <!-- [m] -->
  <!-- Camera joint -->
  <!-- Is located between the two back screw holes at ground level. -->
  <joint name="face_rear_B_to_depth_camera_rear_B_camera" type="fixed">
    <parent link="face_rear_B"/>
    <child link="depth_camera_rear_B_camera"/>
    <origin rpy="0.0 0.5235987755982988 0" xyz="0.04715 0.0 -0.0292"/>
  </joint>
  <!-- Camera link -->
  <link name="depth_camera_rear_B_camera">
    <visual>
      <origin rpy="0 0 0" xyz="0.0 0.0 0.0"/>
      <geometry>
        <mesh filename="../meshes/realsense_d435_3_1_1_mesh.dae" scale="1.0 1.0 1.0"/>
      </geometry>
    </visual>
    <inertial>
      <origin rpy="0 0 0" xyz="-0.021 -0.002 0.025"/>
      <mass value="0.16043"/>
      <inertia ixx="0.000637051" ixy="0.000484569" ixz="0.000424211" iyy="0.000929402" iyz="5.138e-06" izz="0.000484569"/>
    </inertial>
  </link>
  <!-- Camera parent joint -->
  <!-- Frame lies on the left ir camera according to any_realsense2_camera urdf. -->
  <joint name="depth_camera_rear_B_camera_to_camera_parent" type="fixed">
    <parent link="depth_camera_rear_B_camera"/>
    <child link="depth_camera_rear_B_camera_parent"/>
    <origin rpy="0.0 0.0 0.0" xyz="0.0255 0.0175 0.0"/>
  </joint>
  <!-- Camera parent link -->
  <link name="depth_camera_rear_B_camera_parent"/>
  <!-- simulation or bagfile_is_played -->
  <!-- simulation -->
  <!-- [kg * m^2] -->
  <!-- [m] -->
  <!-- Camera joint -->
  <!-- Is located in the center of the mounting points. -->
  <joint name="face_rear_B_to_wide_angle_camera_rear_B_camera" type="fixed">
    <parent link="face_rear_B"/>
    <child link="wide_angle_camera_rear_B_camera"/>
    <origin rpy="0 0 0" xyz="0.09850 0.0 0.01497"/>
  </joint>
  <!-- Camera link -->
  <link name="wide_angle_camera_rear_B_camera">
    <visual>
      <origin rpy="0 0 0" xyz="0.0 0.0 0.0"/>
      <geometry>
        <mesh filename="../meshes/blackfly_3_1_1_mesh.dae" scale="1.0 1.0 1.0"/>
      </geometry>
    </visual>
    <inertial>
      <origin rpy="0 0 0" xyz="-0.053 -0.001 0.025"/>
      <mass value="0.287"/>
      <inertia ixx="0.000559232" ixy="1.6875e-05" ixz="0.000423761" iyy="0.000946504" iyz="1.3234e-07" izz="0.000493052"/>
    </inertial>
  </link>
  <!-- Camera parent joint -->
  <joint name="wide_angle_camera_rear_B_camera_to_camera_parent" type="fixed">
    <parent link="wide_angle_camera_rear_B_camera"/>
    <child link="wide_angle_camera_rear_B_camera_parent"/>
    <origin rpy="-1.5707963267948966 0.0 -1.5707963267948966" xyz="0.0 0.0 0.0"/>
  </joint>
  <!-- Camera parent link -->
  <link name="wide_angle_camera_rear_B_camera_parent"/>
  <!-- simulation -->
  <!-- [kg * m^2] -->
  <!-- Fixed joint base battery -->
  <joint name="base_battery_B" type="fixed">
    <parent link="base_B"/>
    <child link="battery_B"/>
    <origin rpy="0 0 0" xyz="0 0 0"/>
  </joint>
  <!-- Shell link -->
  <link name="battery_B">
    <visual>
      <origin rpy="0 0 0" xyz="0 0 0"/>
      <geometry>
        <mesh filename="../meshes/battery_3_0_4_mesh.dae" scale="1.0 1.0     1.0"/>
      </geometry>
    </visual>
    <inertial>
      <origin rpy="0 0 0" xyz="-0.00067 -0.00023 -0.03362"/>
      <mass value="5.53425"/>
      <inertia ixx="0.00749474794" ixy="0.00016686282" ixz="7.82763e-05" iyy="0.0722338913" iyz="1.42902e-06" izz="0.07482717535"/>
    </inertial>
  </link>
  <!-- [kg * m^2] -->
  <!-- Fixed joint to add docking  -->
  <joint name="base_to_docking_hatch_cover_B" type="fixed">
    <parent link="base_B"/>
    <child link="docking_hatch_cover_B"/>
    <origin rpy="0 0 0" xyz="0.343 0.0 -0.07"/>
  </joint>
  <!-- Hatch cover link -->
  <link name="docking_hatch_cover_B">
    <!--  TODO(fgiraldez): add visual    -->
    <inertial>
      <origin rpy="0 0 0" xyz="-0.003 0.0 0.005"/>
      <mass value="0.065"/>
      <inertia ixx="0.00063283" ixy="0.0" ixz="3.45e-07" iyy="0.00110971" iyz="0.0" izz="0.00171883"/>
    </inertial>
  </link>
  <!-- [] -->
  <link name="imu_B_link">
    <visual>
      <origin rpy="0 0 0" xyz="0 0 0.005"/>
      <geometry>
        <box size="0.024 0.024 0.01"/>
      </geometry>
      <material name="orange"/>
    </visual>
    <collision>
      <origin rpy="0 0 0" xyz="0 0 0.005"/>
      <geometry>
        <box size="0.024 0.024 0.01"/>
      </geometry>
    </collision>
    <inertial>
      <mass value="0.01"/>
      <origin xyz="0 0 0"/>
      <inertia ixx="5.633333333333334e-07" ixy="0.0" ixz="0.0" iyy="9.6e-07" iyz="0.0" izz="5.633333333333334e-07"/>
    </inertial>
  </link>
  <joint name="imu_B_joint" type="fixed">
    <parent link="base_B"/>
    <child link="imu_B_link"/>
    <origin rpy="0.0 0.0 1.5707963267948966" xyz="0.2488 0.00835 0.04628"/>
  </joint>
  <gazebo reference="imu_B_link">
    <material>Gazebo/Orange</material>
    <mu1>0.8</mu1>
    <mu2>0.8</mu2>
  </gazebo>
  <gazebo reference="imu_B_joint">
      </gazebo>
  <gazebo>
    <plugin filename="libany_hector_gazebo_ros_imu.so" name="imu_B_plugin">
      <robotNamespace>sensors</robotNamespace>
      <bodyName>imu_B_link</bodyName>
      <frameId>imu_link</frameId>
      <topicName>imu</topicName>
      <biasTopicName>imu/bias</biasTopicName>
      <serviceName>imu/calibrate</serviceName>
      <updateRate>400</updateRate>
    </plugin>
  </gazebo>
  <!-- [kg * m^2] -->
  <!-- [m] -->
  <!-- Camera joint -->
  <!-- Is located between the two back screw holes at ground level. -->
  <joint name="base_B_to_depth_camera_left_B_camera" type="fixed">
    <parent link="base_B"/>
    <child link="depth_camera_left_B_camera"/>
    <origin rpy="0.0 0.5235987755982988 1.5707963267948966" xyz="0.0 0.07646 0.02905"/>
  </joint>
  <!-- Camera link -->
  <link name="depth_camera_left_B_camera">
    <visual>
      <origin rpy="0 0 0" xyz="0.0 0.0 0.0"/>
      <geometry>
        <mesh filename="../meshes/realsense_d435_3_1_1_mesh.dae" scale="1.0 1.0 1.0"/>
      </geometry>
    </visual>
    <inertial>
      <origin rpy="0 0 0" xyz="-0.021 -0.002 0.025"/>
      <mass value="0.16043"/>
      <inertia ixx="0.000637051" ixy="0.000484569" ixz="0.000424211" iyy="0.000929402" iyz="5.138e-06" izz="0.000484569"/>
    </inertial>
  </link>
  <!-- Camera parent joint -->
  <!-- Frame lies on the left ir camera according to any_realsense2_camera urdf. -->
  <joint name="depth_camera_left_B_camera_to_camera_parent" type="fixed">
    <parent link="depth_camera_left_B_camera"/>
    <child link="depth_camera_left_B_camera_parent"/>
    <origin rpy="0.0 0.0 0.0" xyz="0.0255 0.0175 0.0"/>
  </joint>
  <!-- Camera parent link -->
  <link name="depth_camera_left_B_camera_parent"/>
  <!-- simulation or bagfile_is_played -->
  <!-- simulation -->
  <!-- [kg * m^2] -->
  <!-- [m] -->
  <!-- Camera joint -->
  <!-- Is located between the two back screw holes at ground level. -->
  <joint name="base_B_to_depth_camera_right_B_camera" type="fixed">
    <parent link="base_B"/>
    <child link="depth_camera_right_B_camera"/>
    <origin rpy="0.0 0.5235987755982988 -1.5707963267948966" xyz="0.0 -0.07646 0.02905"/>
  </joint>
  <!-- Camera link -->
  <link name="depth_camera_right_B_camera">
    <visual>
      <origin rpy="0 0 0" xyz="0.0 0.0 0.0"/>
      <geometry>
        <mesh filename="../meshes/realsense_d435_3_1_1_mesh.dae" scale="1.0 1.0 1.0"/>
      </geometry>
    </visual>
    <inertial>
      <origin rpy="0 0 0" xyz="-0.021 -0.002 0.025"/>
      <mass value="0.16043"/>
      <inertia ixx="0.000637051" ixy="0.000484569" ixz="0.000424211" iyy="0.000929402" iyz="5.138e-06" izz="0.000484569"/>
    </inertial>
  </link>
  <!-- Camera parent joint -->
  <!-- Frame lies on the left ir camera according to any_realsense2_camera urdf. -->
  <joint name="depth_camera_right_B_camera_to_camera_parent" type="fixed">
    <parent link="depth_camera_right_B_camera"/>
    <child link="depth_camera_right_B_camera_parent"/>
    <origin rpy="0.0 0.0 0.0" xyz="0.0255 0.0175 0.0"/>
  </joint>
  <!-- Camera parent link -->
  <link name="depth_camera_right_B_camera_parent"/>
  <!-- simulation or bagfile_is_played -->
  <!-- simulation -->
  <!-- [kg * m^2] -->
  <!-- [m] -->
  <!-- parent to cage joint, located between mounting plate on trunk and the cage -->
  <joint name="base_B_to_lidar_B_cage" type="fixed">
    <parent link="base_B"/>
    <child link="lidar_B_cage"/>
    <origin rpy="0 0 0" xyz="-0.364 0.0 0.0735"/>
  </joint>
  <!-- Velodyne cage link -->
  <link name="lidar_B_cage">
    <visual>
      <origin rpy="0.0 0.0 0.0" xyz="0.0 0.0 0.0"/>
      <geometry>
        <mesh filename="../meshes/cage_3_1_1_mesh.dae" scale="1.0 1.0 1.0"/>
      </geometry>
    </visual>
    <collision>
      <origin rpy="0 0 0" xyz="0 0 0.06"/>
      <geometry>
        <cylinder length="0.12" radius="0.07"/>
      </geometry>
    </collision>
    <inertial>
      <origin rpy="0.0 0.0 0.0" xyz="0.002 0.0 0.099"/>
      <mass value="0.545"/>
      <inertia ixx="0.003156254" ixy="0.0" ixz="1.0992e-05" iyy="0.002357216" iyz="0.0" izz="0.001326455"/>
    </inertial>
  </link>
  <!-- [kg * m^2] -->
  <!-- parent to sensor joint -->
  <joint name="lidar_B_cage_to_lidar_B" type="fixed">
    <parent link="lidar_B_cage"/>
    <child link="lidar_B"/>
    <origin rpy="0.0 0.0 -1.5707963267948966" xyz="0.0 0.0 0.0687"/>
  </joint>
  <!-- Velodyne sensor link -->
  <link name="lidar_B">
    <inertial>
      <origin rpy="0.0 0.0 0.0" xyz="-0.012 0.001 -0.008"/>
      <mass value="0.695"/>
      <inertia ixx="0.000846765" ixy="6.9565e-05" ixz="0.00027111" iyy="0.001367583" iyz="5.8984e-05" izz="0.001363673"/>
    </inertial>
    <visual>
      <origin xyz="0 0 0"/>
      <geometry>
        <mesh filename="../meshes/velodyne_3_1_1_mesh.dae"/>
      </geometry>
    </visual>
  </link>
  <!-- simulation -->
  <joint name="base_B_to_linkage" type="fixed">
    <parent link="base_link"/>
    <child link="base_B"/>
    <origin rpy="0 0 1.57079633" xyz="0.6 0 -0.35"/>
  </joint>
  <!--xacro:if value="${version_ != 'c100'}">
      <xacro:include filename="$(find anymal_c)/urdf/base/base_3_0_macro.urdf.xacro"/>
      <xacro:base fix_base="$(arg fix_base)"
                  simulate_depth_camera="$(arg simulate_depth_camera)"
                  simulate_lidar="$(arg simulate_lidar)"
                  simulate_wide_angle_camera="$(arg simulate_wide_angle_camera)"
                  version="${version_}"
                  depth_camera_front_roll="$(arg depth_camera_front_roll)"
                  depth_camera_front_pitch="$(arg depth_camera_front_pitch)"
                  depth_camera_rear_roll="$(arg depth_camera_rear_roll)"
                  depth_camera_rear_pitch="$(arg depth_camera_rear_pitch)"
                  depth_camera_left_roll="$(arg depth_camera_left_roll)"
                  depth_camera_left_pitch="$(arg depth_camera_left_pitch)"
                  depth_camera_right_roll="$(arg depth_camera_right_roll)"
                  depth_camera_right_pitch="$(arg depth_camera_right_pitch)"
                  imu_model="$(arg imu_model)"
                  imu_roll="$(arg imu_roll)"
                  imu_pitch="$(arg imu_pitch)"
                  imu_yaw="$(arg imu_yaw)"
                  battery_model="$(arg battery_model)"
                  docking_socket="$(arg docking_socket)"
                  m_B="$(arg m_B)"
                  B_r_BBcom_x="$(arg B_r_BBcom_x)"
                  B_r_BBcom_y="$(arg B_r_BBcom_y)"
                  B_r_BBcom_z="$(arg B_r_BBcom_z)"/>
    </xacro:if-->
  <!-- Legs -->
  <!--xacro:if value="${version_ == 'c010'}">
      <xacro:include filename="$(find anymal_c)/urdf/leg/leg_3_0_macro.urdf.xacro"/>
    </xacro:if>

    <xacro:if value="${version_ == 'c020'}">
      <xacro:include filename="$(find anymal_c)/urdf/leg/leg_3_0_1_macro.urdf.xacro"/>
    </xacro:if-->
  <!-- [rad] -->
  <!-- [rad] -->
  <!-- joint base HAA -->
  <joint name="base_LF_HAA_B" type="fixed">
    <parent link="base_B"/>
    <child link="LF_HAA_B"/>
    <origin rpy="2.6179938779914944 0 0.0" xyz="0.2999 0.104 0.0"/>
  </joint>
  <!-- [m] -->
  <!-- [A] -->
  <!-- Drive link -->
  <link name="LF_HAA_B">
    <visual>
      <origin rpy="0 0 0" xyz="0 0 0"/>
      <geometry>
        <mesh filename="../meshes/drive_3_0_2_mesh.dae" scale="1.0 1.0     1.0"/>
      </geometry>
    </visual>
    <inertial>
      <origin rpy="0 0 0" xyz="-0.063 7e-05 0.00046"/>
      <mass value="2.04"/>
      <inertia ixx="0.001053013" ixy="4.527e-05" ixz="8.855e-05" iyy="0.001805509" iyz="9.909e-05" izz="0.001765827"/>
    </inertial>
  </link>
  <!-- joint Drive output -->
  <joint name="LF_HAA_B" type="revolute">
    <parent link="LF_HAA_B"/>
    <child link="LF_HIP_B"/>
    <origin rpy="0 0 0" xyz="0 0 0"/>
    <axis xyz="1 0 0"/>
    <limit command_effort="80.0" current="32.0" effort="80.0" gear_velocity="7.5" lower="-0.72" upper="0.49" velocity="7.5"/>
    <dynamics damping="0.0" friction="0.0"/>
  </joint>
  <!-- Drive output link -->
  <link name="LF_HIP_B">
    <inertial>
      <origin rpy="0 0 0" xyz="0 0 0"/>
      <mass value="0.001"/>
      <inertia ixx="0.000001" ixy="0.0" ixz="0.0" iyy="0.000001" iyz="0.0" izz="0.000001"/>
    </inertial>
  </link>
  <!-- [kg * m^2] -->
  <!-- joint HAA hip -->
  <joint name="LF_HIP_LF_hip_fixed_B" type="fixed">
    <parent link="LF_HIP_B"/>
    <child link="LF_hip_fixed_B"/>
    <origin rpy="-2.6179938779914944 0 0.0" xyz="0 0 0"/>
  </joint>
  <!-- Hip link -->
  <link name="LF_hip_fixed_B">
    <visual>
      <origin rpy="0 0 0.0" xyz="0 0 0"/>
      <geometry>
        <mesh filename="../meshes/hip_3_1_1_mesh.dae" scale="1.0 1.0     1.0"/>
      </geometry>
    </visual>
    <inertial>
      <origin rpy="0 0 0" xyz="0.048 0.008 -0.003"/>
      <mass value="0.74"/>
      <inertia ixx="0.001393106" ixy="8.4012e-05" ixz="2.3378e-05" iyy="0.003798579" iyz="7.1319e-05" izz="0.003897509"/>
    </inertial>
  </link>
  <!-- [rad] -->
  <!-- joint hip HFE -->
  <joint name="LF_hip_fixed_LF_HFE_B" type="fixed">
    <parent link="LF_hip_fixed_B"/>
    <child link="LF_HFE_B"/>
    <origin rpy="0 0 1.5707963267948966" xyz="0.0599 0.08381 0.0"/>
  </joint>
  <!-- [m] -->
  <!-- [A] -->
  <!-- Drive link -->
  <link name="LF_HFE_B">
    <visual>
      <origin rpy="0 0 0" xyz="0 0 0"/>
      <geometry>
        <mesh filename="../meshes/drive_3_0_2_mesh.dae" scale="1.0 1.0     1.0"/>
      </geometry>
    </visual>
    <collision>
      <origin rpy="0 1.5707963267948966 0" xyz="-0.07 0 0"/>
      <geometry>
        <cylinder length="0.14" radius="0.05"/>
      </geometry>
    </collision>
    <inertial>
      <origin rpy="0 0 0" xyz="-0.063 7e-05 0.00046"/>
      <mass value="2.04"/>
      <inertia ixx="0.001053013" ixy="4.527e-05" ixz="8.855e-05" iyy="0.001805509" iyz="9.909e-05" izz="0.001765827"/>
    </inertial>
  </link>
  <!-- joint Drive output -->
  <joint name="LF_HFE_B" type="revolute">
    <parent link="LF_HFE_B"/>
    <child link="LF_THIGH_B"/>
    <origin rpy="0 0 0" xyz="0 0 0"/>
    <axis xyz="1 0 0"/>
    <limit command_effort="80.0" current="32.0" effort="80.0" gear_velocity="7.5" lower="-9.42477796076938" upper="9.42477796076938" velocity="7.5"/>
    <dynamics damping="0.0" friction="0.0"/>
  </joint>
  <!-- Drive output link -->
  <link name="LF_THIGH_B">
    <inertial>
      <origin rpy="0 0 0" xyz="0 0 0"/>
      <mass value="0.001"/>
      <inertia ixx="0.000001" ixy="0.0" ixz="0.0" iyy="0.000001" iyz="0.0" izz="0.000001"/>
    </inertial>
  </link>
  <!-- [m] -->
  <!-- measured -->
  <!-- joint HFE thigh -->
  <joint name="LF_THIGH_LF_thigh_fixed_B" type="fixed">
    <parent link="LF_THIGH_B"/>
    <child link="LF_thigh_fixed_B"/>
    <origin rpy="0 0 -1.5707963267948966" xyz="0 0 0"/>
  </joint>
  <!-- Thigh link -->
  <link name="LF_thigh_fixed_B">
    <visual>
      <origin rpy="0 0 0.0" xyz="0 0 0"/>
      <geometry>
        <mesh filename="../meshes/thigh_3_1_1_mesh.dae" scale="1.0 1.0     1.0"/>
      </geometry>
    </visual>
    <!-- Thigh collision -->
    <collision>
      <origin rpy="1.5707963267948966 0 0" xyz="0 0.04 0"/>
      <geometry>
        <cylinder length="0.08" radius="0.065"/>
      </geometry>
    </collision>
    <collision>
      <origin rpy="0 0 0" xyz="0 0.03 -0.1413135"/>
      <geometry>
        <box size="0.07500000000000001 0.06 0.282627"/>
      </geometry>
    </collision>
    <inertial>
      <origin rpy="0 0 0" xyz="0.0 0.018 -0.169"/>
      <mass value="1.03"/>
      <inertia ixx="0.018644469" ixy="5.2e-08" ixz="1.0157e-05" iyy="0.019312599" iyz="0.002520077" izz="0.002838361"/>
    </inertial>
  </link>
  <!-- [rad] -->
  <!-- joint thigh KFE -->
  <joint name="LF_thigh_fixed_LF_KFE_B" type="fixed">
    <parent link="LF_thigh_fixed_B"/>
    <child link="LF_KFE_B"/>
    <origin rpy="0 0 1.5707963267948966" xyz="0.0 0.1003 -0.285"/>
  </joint>
  <!-- [m] -->
  <!-- [A] -->
  <!-- Drive link -->
  <link name="LF_KFE_B">
    <visual>
      <origin rpy="0 0 0" xyz="0 0 0"/>
      <geometry>
        <mesh filename="../meshes/drive_3_0_2_mesh.dae" scale="1.0 1.0     1.0"/>
      </geometry>
    </visual>
    <collision>
      <origin rpy="0 1.5707963267948966 0" xyz="-0.07 0 0"/>
      <geometry>
        <cylinder length="0.14" radius="0.05"/>
      </geometry>
    </collision>
    <inertial>
      <origin rpy="0 0 0" xyz="-0.063 7e-05 0.00046"/>
      <mass value="2.04"/>
      <inertia ixx="0.001053013" ixy="4.527e-05" ixz="8.855e-05" iyy="0.001805509" iyz="9.909e-05" izz="0.001765827"/>
    </inertial>
  </link>
  <!-- joint Drive output -->
  <joint name="LF_KFE_B" type="revolute">
    <parent link="LF_KFE_B"/>
    <child link="LF_SHANK_B"/>
    <origin rpy="0 0 0" xyz="0 0 0"/>
    <axis xyz="1 0 0"/>
    <limit command_effort="80.0" current="32.0" effort="80.0" gear_velocity="7.5" lower="-9.42477796076938" upper="9.42477796076938" velocity="7.5"/>
    <dynamics damping="0.0" friction="0.0"/>
  </joint>
  <!-- Drive output link -->
  <link name="LF_SHANK_B">
    <inertial>
      <origin rpy="0 0 0" xyz="0 0 0"/>
      <mass value="0.001"/>
      <inertia ixx="0.000001" ixy="0.0" ixz="0.0" iyy="0.000001" iyz="0.0" izz="0.000001"/>
    </inertial>
  </link>
  <!-- [m] -->
  <!-- measured -->
  <!-- joint KFE shank -->
  <joint name="LF_shank_LF_shank_fixed_B" type="fixed">
    <parent link="LF_SHANK_B"/>
    <child link="LF_shank_fixed_B"/>
    <origin rpy="0 0 -1.5707963267948966" xyz="0 0 0"/>
  </joint>
  <!-- Shank link -->
  <link name="LF_shank_fixed_B">
    <visual>
      <origin rpy="0 0 0.0" xyz="0 0 0"/>
      <geometry>
        <mesh filename="../meshes/shank_3_1_1_mesh.dae" scale="1.0 1.0     1.0"/>
      </geometry>
    </visual>
    <!-- Shank collision -->
    <collision>
      <origin rpy="1.5707963267948966 0 0" xyz="0 0.02 0"/>
      <geometry>
        <cylinder length="0.04" radius="0.06"/>
      </geometry>
    </collision>
    <collision>
      <origin rpy="1.5707963267948966 0 0" xyz="0.057499 0.02 0"/>
      <geometry>
        <box size="0.114998 0.0675 0.04"/>
      </geometry>
    </collision>
    <inertial>
      <origin rpy="0 0 0" xyz="0.03463 0.00688 0.00098"/>
      <mass value="0.33742"/>
      <inertia ixx="0.00032748005" ixy="2.142561e-05" ixz="1.33942e-05" iyy="0.00110974122" iyz="7.601e-08" izz="0.00089388521"/>
    </inertial>
  </link>
  <!-- Leg configurations: xx (knees bent inwards), xo (knees bent backwards) -->
  <!-- joint shank foot -->
  <joint name="LF_shank_fixed_LF_FOOT_B" type="fixed">
    <parent link="LF_shank_fixed_B"/>
    <child link="LF_FOOT_B"/>
    <origin rpy="0 0 0" xyz="0.08795 0.01305 -0.33797"/>
  </joint>
  <!-- Foot link -->
  <link name="LF_FOOT_B">
    <visual>
      <origin rpy="0 0 -0.7853981633974483" xyz="0 0 0"/>
      <geometry>
        <mesh filename="../meshes/foot_3_1_1_mesh.dae" scale="1.0 1.0     1.0"/>
      </geometry>
    </visual>
    <!-- Adapter collision -->
    <collision>
      <origin rpy="0 0 0" xyz="0 0 0.168985"/>
      <geometry>
        <cylinder length="0.282504" radius="0.0175"/>
      </geometry>
    </collision>
    <!-- Foot collision -->
    <collision>
      <origin xyz="0 0 0.0225"/>
      <geometry>
        <sphere radius="0.03"/>
      </geometry>
    </collision>
    <inertial>
      <origin rpy="0 0 0" xyz="0.00948 -0.00948 0.1468"/>
      <mass value="0.25"/>
      <inertia ixx="0.00317174097" ixy="2.63048e-06" ixz="6.815581e-05" iyy="0.00317174092" iyz="6.815583e-05" izz="8.319196e-05"/>
    </inertial>
  </link>
  <!-- Gazebo customization -->
  <gazebo reference="LF_FOOT_B">
    <kp>1000000.0</kp>
    <kd>100.0</kd>
    <mu1>0.8</mu1>
    <mu2>0.8</mu2>
  </gazebo>
  <!-- [rad] -->
  <!-- [rad] -->
  <!-- joint base HAA -->
  <joint name="base_RF_HAA_B" type="fixed">
    <parent link="base_B"/>
    <child link="RF_HAA_B"/>
    <origin rpy="-2.6179938779914944 0 0.0" xyz="0.2999 -0.104 0.0"/>
  </joint>
  <!-- [m] -->
  <!-- [A] -->
  <!-- Drive link -->
  <link name="RF_HAA_B">
    <visual>
      <origin rpy="0 0 0" xyz="0 0 0"/>
      <geometry>
        <mesh filename="../meshes/drive_3_0_2_mesh.dae" scale="1.0 1.0     1.0"/>
      </geometry>
    </visual>
    <inertial>
      <origin rpy="0 0 0" xyz="-0.063 7e-05 0.00046"/>
      <mass value="2.04"/>
      <inertia ixx="0.001053013" ixy="4.527e-05" ixz="8.855e-05" iyy="0.001805509" iyz="9.909e-05" izz="0.001765827"/>
    </inertial>
  </link>
  <!-- joint Drive output -->
  <joint name="RF_HAA_B" type="revolute">
    <parent link="RF_HAA_B"/>
    <child link="RF_HIP_B"/>
    <origin rpy="0 0 0" xyz="0 0 0"/>
    <axis xyz="1 0 0"/>
    <limit command_effort="80.0" current="32.0" effort="80.0" gear_velocity="7.5" lower="-0.49" upper="0.72" velocity="7.5"/>
    <dynamics damping="0.0" friction="0.0"/>
  </joint>
  <!-- Drive output link -->
  <link name="RF_HIP_B">
    <inertial>
      <origin rpy="0 0 0" xyz="0 0 0"/>
      <mass value="0.001"/>
      <inertia ixx="0.000001" ixy="0.0" ixz="0.0" iyy="0.000001" iyz="0.0" izz="0.000001"/>
    </inertial>
  </link>
  <!-- [kg * m^2] -->
  <!-- joint HAA hip -->
  <joint name="RF_HIP_RF_hip_fixed_B" type="fixed">
    <parent link="RF_HIP_B"/>
    <child link="RF_hip_fixed_B"/>
    <origin rpy="2.6179938779914944 0 0.0" xyz="0 0 0"/>
  </joint>
  <!-- Hip link -->
  <link name="RF_hip_fixed_B">
    <visual>
      <origin rpy="0 0 0.0" xyz="0 0 0"/>
      <geometry>
        <mesh filename="../meshes/hip_3_1_1_mesh_mirrored.dae" scale="1.0 1.0     1.0"/>
      </geometry>
    </visual>
    <inertial>
      <origin rpy="0 0 0" xyz="0.048 -0.008 -0.003"/>
      <mass value="0.74"/>
      <inertia ixx="0.001393106" ixy="-8.4012e-05" ixz="2.3378e-05" iyy="0.003798579" iyz="-7.1319e-05" izz="0.003897509"/>
    </inertial>
  </link>
  <!-- [rad] -->
  <!-- joint hip HFE -->
  <joint name="RF_hip_fixed_RF_HFE_B" type="fixed">
    <parent link="RF_hip_fixed_B"/>
    <child link="RF_HFE_B"/>
    <origin rpy="0 0 -1.5707963267948966" xyz="0.0599 -0.08381 0.0"/>
  </joint>
  <!-- [m] -->
  <!-- [A] -->
  <!-- Drive link -->
  <link name="RF_HFE_B">
    <visual>
      <origin rpy="0 0 0" xyz="0 0 0"/>
      <geometry>
        <mesh filename="../meshes/drive_3_0_2_mesh.dae" scale="1.0 1.0     1.0"/>
      </geometry>
    </visual>
    <collision>
      <origin rpy="0 1.5707963267948966 0" xyz="-0.07 0 0"/>
      <geometry>
        <cylinder length="0.14" radius="0.05"/>
      </geometry>
    </collision>
    <inertial>
      <origin rpy="0 0 0" xyz="-0.063 7e-05 0.00046"/>
      <mass value="2.04"/>
      <inertia ixx="0.001053013" ixy="4.527e-05" ixz="8.855e-05" iyy="0.001805509" iyz="9.909e-05" izz="0.001765827"/>
    </inertial>
  </link>
  <!-- joint Drive output -->
  <joint name="RF_HFE_B" type="revolute">
    <parent link="RF_HFE_B"/>
    <child link="RF_THIGH_B"/>
    <origin rpy="0 0 0" xyz="0 0 0"/>
    <axis xyz="-1 0 0"/>
    <limit command_effort="80.0" current="32.0" effort="80.0" gear_velocity="7.5" lower="-9.42477796076938" upper="9.42477796076938" velocity="7.5"/>
    <dynamics damping="0.0" friction="0.0"/>
  </joint>
  <!-- Drive output link -->
  <link name="RF_THIGH_B">
    <inertial>
      <origin rpy="0 0 0" xyz="0 0 0"/>
      <mass value="0.001"/>
      <inertia ixx="0.000001" ixy="0.0" ixz="0.0" iyy="0.000001" iyz="0.0" izz="0.000001"/>
    </inertial>
  </link>
  <!-- [m] -->
  <!-- measured -->
  <!-- joint HFE thigh -->
  <joint name="RF_THIGH_RF_thigh_fixed_B" type="fixed">
    <parent link="RF_THIGH_B"/>
    <child link="RF_thigh_fixed_B"/>
    <origin rpy="0 0 1.5707963267948966" xyz="0 0 0"/>
  </joint>
  <!-- Thigh link -->
  <link name="RF_thigh_fixed_B">
    <visual>
      <origin rpy="0 0 -3.141592653589793" xyz="0 0 0"/>
      <geometry>
        <mesh filename="../meshes/thigh_3_1_1_mesh.dae" scale="1.0 1.0     1.0"/>
      </geometry>
    </visual>
    <!-- Thigh collision -->
    <collision>
      <origin rpy="1.5707963267948966 0 0" xyz="0 -0.04 0"/>
      <geometry>
        <cylinder length="0.08" radius="0.065"/>
      </geometry>
    </collision>
    <collision>
      <origin rpy="0 0 0" xyz="0 -0.03 -0.1413135"/>
      <geometry>
        <box size="0.07500000000000001 0.06 0.282627"/>
      </geometry>
    </collision>
    <inertial>
      <origin rpy="0 0 0" xyz="0.0 -0.018 -0.169"/>
      <mass value="1.03"/>
      <inertia ixx="0.018644469" ixy="-5.2e-08" ixz="1.0157e-05" iyy="0.019312599" iyz="-0.002520077" izz="0.002838361"/>
    </inertial>
  </link>
  <!-- [rad] -->
  <!-- joint thigh KFE -->
  <joint name="RF_thigh_fixed_RF_KFE_B" type="fixed">
    <parent link="RF_thigh_fixed_B"/>
    <child link="RF_KFE_B"/>
    <origin rpy="0 0 -1.5707963267948966" xyz="0.0 -0.1003 -0.285"/>
  </joint>
  <!-- [m] -->
  <!-- [A] -->
  <!-- Drive link -->
  <link name="RF_KFE_B">
    <visual>
      <origin rpy="0 0 0" xyz="0 0 0"/>
      <geometry>
        <mesh filename="../meshes/drive_3_0_2_mesh.dae" scale="1.0 1.0     1.0"/>
      </geometry>
    </visual>
    <collision>
      <origin rpy="0 1.5707963267948966 0" xyz="-0.07 0 0"/>
      <geometry>
        <cylinder length="0.14" radius="0.05"/>
      </geometry>
    </collision>
    <inertial>
      <origin rpy="0 0 0" xyz="-0.063 7e-05 0.00046"/>
      <mass value="2.04"/>
      <inertia ixx="0.001053013" ixy="4.527e-05" ixz="8.855e-05" iyy="0.001805509" iyz="9.909e-05" izz="0.001765827"/>
    </inertial>
  </link>
  <!-- joint Drive output -->
  <joint name="RF_KFE_B" type="revolute">
    <parent link="RF_KFE_B"/>
    <child link="RF_SHANK_B"/>
    <origin rpy="0 0 0" xyz="0 0 0"/>
    <axis xyz="-1 0 0"/>
    <limit command_effort="80.0" current="32.0" effort="80.0" gear_velocity="7.5" lower="-9.42477796076938" upper="9.42477796076938" velocity="7.5"/>
    <dynamics damping="0.0" friction="0.0"/>
  </joint>
  <!-- Drive output link -->
  <link name="RF_SHANK_B">
    <inertial>
      <origin rpy="0 0 0" xyz="0 0 0"/>
      <mass value="0.001"/>
      <inertia ixx="0.000001" ixy="0.0" ixz="0.0" iyy="0.000001" iyz="0.0" izz="0.000001"/>
    </inertial>
  </link>
  <!-- [m] -->
  <!-- measured -->
  <!-- joint KFE shank -->
  <joint name="RF_shank_RF_shank_fixed_B" type="fixed">
    <parent link="RF_SHANK_B"/>
    <child link="RF_shank_fixed_B"/>
    <origin rpy="0 0 1.5707963267948966" xyz="0 0 0"/>
  </joint>
  <!-- Shank link -->
  <link name="RF_shank_fixed_B">
    <visual>
      <origin rpy="0 0 0.0" xyz="0 0 0"/>
      <geometry>
        <mesh filename="../meshes/shank_3_1_1_mesh_mirrored.dae" scale="1.0 1.0     1.0"/>
      </geometry>
    </visual>
    <!-- Shank collision -->
    <collision>
      <origin rpy="1.5707963267948966 0 0" xyz="0 -0.02 0"/>
      <geometry>
        <cylinder length="0.04" radius="0.06"/>
      </geometry>
    </collision>
    <collision>
      <origin rpy="1.5707963267948966 0 0" xyz="0.057499 -0.02 0"/>
      <geometry>
        <box size="0.114998 0.0675 0.04"/>
      </geometry>
    </collision>
    <inertial>
      <origin rpy="0 0 0" xyz="0.03463 -0.00688 0.00098"/>
      <mass value="0.33742"/>
      <inertia ixx="0.00032748005" ixy="-2.142561e-05" ixz="1.33942e-05" iyy="0.00110974122" iyz="-7.601e-08" izz="0.00089388521"/>
    </inertial>
  </link>
  <!-- Leg configurations: xx (knees bent inwards), xo (knees bent backwards) -->
  <!-- joint shank foot -->
  <joint name="RF_shank_fixed_RF_FOOT_B" type="fixed">
    <parent link="RF_shank_fixed_B"/>
    <child link="RF_FOOT_B"/>
    <origin rpy="0 0 0" xyz="0.08795 -0.01305 -0.33797"/>
  </joint>
  <!-- Foot link -->
  <link name="RF_FOOT_B">
    <visual>
      <origin rpy="0 0 0.7853981633974483" xyz="0 0 0"/>
      <geometry>
        <mesh filename="../meshes/foot_3_1_1_mesh.dae" scale="1.0 1.0     1.0"/>
      </geometry>
    </visual>
    <!-- Adapter collision -->
    <collision>
      <origin rpy="0 0 0" xyz="0 0 0.168985"/>
      <geometry>
        <cylinder length="0.282504" radius="0.0175"/>
      </geometry>
    </collision>
    <!-- Foot collision -->
    <collision>
      <origin xyz="0 0 0.0225"/>
      <geometry>
        <sphere radius="0.03"/>
      </geometry>
    </collision>
    <inertial>
      <origin rpy="0 0 0" xyz="0.00948 0.00948 0.1468"/>
      <mass value="0.25"/>
      <inertia ixx="0.00317174097" ixy="-2.63048e-06" ixz="6.815581e-05" iyy="0.00317174092" iyz="-6.815583e-05" izz="8.319196e-05"/>
    </inertial>
  </link>
  <!-- Gazebo customization -->
  <gazebo reference="RF_FOOT_B">
    <kp>1000000.0</kp>
    <kd>100.0</kd>
    <mu1>0.8</mu1>
    <mu2>0.8</mu2>
  </gazebo>
  <!-- [rad] -->
  <!-- [rad] -->
  <!-- joint base HAA -->
  <joint name="base_LH_HAA_B" type="fixed">
    <parent link="base_B"/>
    <child link="LH_HAA_B"/>
    <origin rpy="-2.6179938779914944 0 -3.141592653589793" xyz="-0.2999 0.104 0.0"/>
  </joint>
  <!-- [m] -->
  <!-- [A] -->
  <!-- Drive link -->
  <link name="LH_HAA_B">
    <visual>
      <origin rpy="0 0 0" xyz="0 0 0"/>
      <geometry>
        <mesh filename="../meshes/drive_3_0_2_mesh.dae" scale="1.0 1.0     1.0"/>
      </geometry>
    </visual>
    <inertial>
      <origin rpy="0 0 0" xyz="-0.063 7e-05 0.00046"/>
      <mass value="2.04"/>
      <inertia ixx="0.001053013" ixy="4.527e-05" ixz="8.855e-05" iyy="0.001805509" iyz="9.909e-05" izz="0.001765827"/>
    </inertial>
  </link>
  <!-- joint Drive output -->
  <joint name="LH_HAA_B" type="revolute">
    <parent link="LH_HAA_B"/>
    <child link="LH_HIP_B"/>
    <origin rpy="0 0 0" xyz="0 0 0"/>
    <axis xyz="-1 0 0"/>
    <limit command_effort="80.0" current="32.0" effort="80.0" gear_velocity="7.5" lower="-0.72" upper="0.49" velocity="7.5"/>
    <dynamics damping="0.0" friction="0.0"/>
  </joint>
  <!-- Drive output link -->
  <link name="LH_HIP_B">
    <inertial>
      <origin rpy="0 0 0" xyz="0 0 0"/>
      <mass value="0.001"/>
      <inertia ixx="0.000001" ixy="0.0" ixz="0.0" iyy="0.000001" iyz="0.0" izz="0.000001"/>
    </inertial>
  </link>
  <!-- [kg * m^2] -->
  <!-- joint HAA hip -->
  <joint name="LH_HIP_LH_hip_fixed_B" type="fixed">
    <parent link="LH_HIP_B"/>
    <child link="LH_hip_fixed_B"/>
    <origin rpy="-2.6179938779914944 0 -3.141592653589793" xyz="0 0 0"/>
  </joint>
  <!-- Hip link -->
  <link name="LH_hip_fixed_B">
    <visual>
      <origin rpy="0 0 -3.141592653589793" xyz="0 0 0"/>
      <geometry>
        <mesh filename="../meshes/hip_3_1_1_mesh_mirrored.dae" scale="1.0 1.0     1.0"/>
      </geometry>
    </visual>
    <inertial>
      <origin rpy="0 0 0" xyz="-0.048 0.008 -0.003"/>
      <mass value="0.74"/>
      <inertia ixx="0.001393106" ixy="-8.4012e-05" ixz="-2.3378e-05" iyy="0.003798579" iyz="7.1319e-05" izz="0.003897509"/>
    </inertial>
  </link>
  <!-- [rad] -->
  <!-- joint hip HFE -->
  <joint name="LH_hip_fixed_LH_HFE_B" type="fixed">
    <parent link="LH_hip_fixed_B"/>
    <child link="LH_HFE_B"/>
    <origin rpy="0 0 1.5707963267948966" xyz="-0.0599 0.08381 0.0"/>
  </joint>
  <!-- [m] -->
  <!-- [A] -->
  <!-- Drive link -->
  <link name="LH_HFE_B">
    <visual>
      <origin rpy="0 0 0" xyz="0 0 0"/>
      <geometry>
        <mesh filename="../meshes/drive_3_0_2_mesh.dae" scale="1.0 1.0     1.0"/>
      </geometry>
    </visual>
    <collision>
      <origin rpy="0 1.5707963267948966 0" xyz="-0.07 0 0"/>
      <geometry>
        <cylinder length="0.14" radius="0.05"/>
      </geometry>
    </collision>
    <inertial>
      <origin rpy="0 0 0" xyz="-0.063 7e-05 0.00046"/>
      <mass value="2.04"/>
      <inertia ixx="0.001053013" ixy="4.527e-05" ixz="8.855e-05" iyy="0.001805509" iyz="9.909e-05" izz="0.001765827"/>
    </inertial>
  </link>
  <!-- joint Drive output -->
  <joint name="LH_HFE_B" type="revolute">
    <parent link="LH_HFE_B"/>
    <child link="LH_THIGH_B"/>
    <origin rpy="0 0 0" xyz="0 0 0"/>
    <axis xyz="1 0 0"/>
    <limit command_effort="80.0" current="32.0" effort="80.0" gear_velocity="7.5" lower="-9.42477796076938" upper="9.42477796076938" velocity="7.5"/>
    <dynamics damping="0.0" friction="0.0"/>
  </joint>
  <!-- Drive output link -->
  <link name="LH_THIGH_B">
    <inertial>
      <origin rpy="0 0 0" xyz="0 0 0"/>
      <mass value="0.001"/>
      <inertia ixx="0.000001" ixy="0.0" ixz="0.0" iyy="0.000001" iyz="0.0" izz="0.000001"/>
    </inertial>
  </link>
  <!-- [m] -->
  <!-- measured -->
  <!-- joint HFE thigh -->
  <joint name="LH_THIGH_LH_thigh_fixed_B" type="fixed">
    <parent link="LH_THIGH_B"/>
    <child link="LH_thigh_fixed_B"/>
    <origin rpy="0 0 -1.5707963267948966" xyz="0 0 0"/>
  </joint>
  <!-- Thigh link -->
  <link name="LH_thigh_fixed_B">
    <visual>
      <origin rpy="0 0 0.0" xyz="0 0 0"/>
      <geometry>
        <mesh filename="../meshes/thigh_3_1_1_mesh.dae" scale="1.0 1.0     1.0"/>
      </geometry>
    </visual>
    <!-- Thigh collision -->
    <collision>
      <origin rpy="1.5707963267948966 0 0" xyz="0 0.04 0"/>
      <geometry>
        <cylinder length="0.08" radius="0.065"/>
      </geometry>
    </collision>
    <collision>
      <origin rpy="0 0 0" xyz="0 0.03 -0.1413135"/>
      <geometry>
        <box size="0.07500000000000001 0.06 0.282627"/>
      </geometry>
    </collision>
    <inertial>
      <origin rpy="0 0 0" xyz="-0.0 0.018 -0.169"/>
      <mass value="1.03"/>
      <inertia ixx="0.018644469" ixy="-5.2e-08" ixz="-1.0157e-05" iyy="0.019312599" iyz="0.002520077" izz="0.002838361"/>
    </inertial>
  </link>
  <!-- [rad] -->
  <!-- joint thigh KFE -->
  <joint name="LH_thigh_fixed_LH_KFE_B" type="fixed">
    <parent link="LH_thigh_fixed_B"/>
    <child link="LH_KFE_B"/>
    <origin rpy="0 0 1.5707963267948966" xyz="-0.0 0.1003 -0.285"/>
  </joint>
  <!-- [m] -->
  <!-- [A] -->
  <!-- Drive link -->
  <link name="LH_KFE_B">
    <visual>
      <origin rpy="0 0 0" xyz="0 0 0"/>
      <geometry>
        <mesh filename="../meshes/drive_3_0_2_mesh.dae" scale="1.0 1.0     1.0"/>
      </geometry>
    </visual>
    <collision>
      <origin rpy="0 1.5707963267948966 0" xyz="-0.07 0 0"/>
      <geometry>
        <cylinder length="0.14" radius="0.05"/>
      </geometry>
    </collision>
    <inertial>
      <origin rpy="0 0 0" xyz="-0.063 7e-05 0.00046"/>
      <mass value="2.04"/>
      <inertia ixx="0.001053013" ixy="4.527e-05" ixz="8.855e-05" iyy="0.001805509" iyz="9.909e-05" izz="0.001765827"/>
    </inertial>
  </link>
  <!-- joint Drive output -->
  <joint name="LH_KFE_B" type="revolute">
    <parent link="LH_KFE_B"/>
    <child link="LH_SHANK_B"/>
    <origin rpy="0 0 0" xyz="0 0 0"/>
    <axis xyz="1 0 0"/>
    <limit command_effort="80.0" current="32.0" effort="80.0" gear_velocity="7.5" lower="-9.42477796076938" upper="9.42477796076938" velocity="7.5"/>
    <dynamics damping="0.0" friction="0.0"/>
  </joint>
  <!-- Drive output link -->
  <link name="LH_SHANK_B">
    <inertial>
      <origin rpy="0 0 0" xyz="0 0 0"/>
      <mass value="0.001"/>
      <inertia ixx="0.000001" ixy="0.0" ixz="0.0" iyy="0.000001" iyz="0.0" izz="0.000001"/>
    </inertial>
  </link>
  <!-- [m] -->
  <!-- measured -->
  <!-- joint KFE shank -->
  <joint name="LH_shank_LH_shank_fixed_B" type="fixed">
    <parent link="LH_SHANK_B"/>
    <child link="LH_shank_fixed_B"/>
    <origin rpy="0 0 -1.5707963267948966" xyz="0 0 0"/>
  </joint>
  <!-- Shank link -->
  <link name="LH_shank_fixed_B">
    <visual>
      <origin rpy="0 0 -3.141592653589793" xyz="0 0 0"/>
      <geometry>
        <mesh filename="../meshes/shank_3_1_1_mesh_mirrored.dae" scale="1.0 1.0     1.0"/>
      </geometry>
    </visual>
    <!-- Shank collision -->
    <collision>
      <origin rpy="1.5707963267948966 0 0" xyz="0 0.02 0"/>
      <geometry>
        <cylinder length="0.04" radius="0.06"/>
      </geometry>
    </collision>
    <collision>
      <origin rpy="1.5707963267948966 0 0" xyz="-0.057499 0.02 0"/>
      <geometry>
        <box size="0.114998 0.0675 0.04"/>
      </geometry>
    </collision>
    <inertial>
      <origin rpy="0 0 0" xyz="-0.03463 0.00688 0.00098"/>
      <mass value="0.33742"/>
      <inertia ixx="0.00032748005" ixy="-2.142561e-05" ixz="-1.33942e-05" iyy="0.00110974122" iyz="7.601e-08" izz="0.00089388521"/>
    </inertial>
  </link>
  <!-- Leg configurations: xx (knees bent inwards), xo (knees bent backwards) -->
  <!-- joint shank foot -->
  <joint name="LH_shank_fixed_LH_FOOT_B" type="fixed">
    <parent link="LH_shank_fixed_B"/>
    <child link="LH_FOOT_B"/>
    <origin rpy="0 0 0" xyz="-0.08795 0.01305 -0.33797"/>
  </joint>
  <!-- Foot link -->
  <link name="LH_FOOT_B">
    <visual>
      <origin rpy="0 0 -2.356194490192345" xyz="0 0 0"/>
      <geometry>
        <mesh filename="../meshes/foot_3_1_1_mesh.dae" scale="1.0 1.0     1.0"/>
      </geometry>
    </visual>
    <!-- Adapter collision -->
    <collision>
      <origin rpy="0 0 0" xyz="0 0 0.168985"/>
      <geometry>
        <cylinder length="0.282504" radius="0.0175"/>
      </geometry>
    </collision>
    <!-- Foot collision -->
    <collision>
      <origin xyz="0 0 0.0225"/>
      <geometry>
        <sphere radius="0.03"/>
      </geometry>
    </collision>
    <inertial>
      <origin rpy="0 0 0" xyz="-0.00948 -0.00948 0.1468"/>
      <mass value="0.25"/>
      <inertia ixx="0.00317174097" ixy="-2.63048e-06" ixz="-6.815581e-05" iyy="0.00317174092" iyz="6.815583e-05" izz="8.319196e-05"/>
    </inertial>
  </link>
  <!-- Gazebo customization -->
  <gazebo reference="LH_FOOT_B">
    <kp>1000000.0</kp>
    <kd>100.0</kd>
    <mu1>0.8</mu1>
    <mu2>0.8</mu2>
  </gazebo>
  <!-- [rad] -->
  <!-- [rad] -->
  <!-- joint base HAA -->
  <joint name="base_RH_HAA_B" type="fixed">
    <parent link="base_B"/>
    <child link="RH_HAA_B"/>
    <origin rpy="2.6179938779914944 0 -3.141592653589793" xyz="-0.2999 -0.104 0.0"/>
  </joint>
  <!-- [m] -->
  <!-- [A] -->
  <!-- Drive link -->
  <link name="RH_HAA_B">
    <visual>
      <origin rpy="0 0 0" xyz="0 0 0"/>
      <geometry>
        <mesh filename="../meshes/drive_3_0_2_mesh.dae" scale="1.0 1.0     1.0"/>
      </geometry>
    </visual>
    <inertial>
      <origin rpy="0 0 0" xyz="-0.063 7e-05 0.00046"/>
      <mass value="2.04"/>
      <inertia ixx="0.001053013" ixy="4.527e-05" ixz="8.855e-05" iyy="0.001805509" iyz="9.909e-05" izz="0.001765827"/>
    </inertial>
  </link>
  <!-- joint Drive output -->
  <joint name="RH_HAA_B" type="revolute">
    <parent link="RH_HAA_B"/>
    <child link="RH_HIP_B"/>
    <origin rpy="0 0 0" xyz="0 0 0"/>
    <axis xyz="-1 0 0"/>
    <limit command_effort="80.0" current="32.0" effort="80.0" gear_velocity="7.5" lower="-0.49" upper="0.72" velocity="7.5"/>
    <dynamics damping="0.0" friction="0.0"/>
  </joint>
  <!-- Drive output link -->
  <link name="RH_HIP_B">
    <inertial>
      <origin rpy="0 0 0" xyz="0 0 0"/>
      <mass value="0.001"/>
      <inertia ixx="0.000001" ixy="0.0" ixz="0.0" iyy="0.000001" iyz="0.0" izz="0.000001"/>
    </inertial>
  </link>
  <!-- [kg * m^2] -->
  <!-- joint HAA hip -->
  <joint name="RH_HIP_RH_hip_fixed_B" type="fixed">
    <parent link="RH_HIP_B"/>
    <child link="RH_hip_fixed_B"/>
    <origin rpy="2.6179938779914944 0 -3.141592653589793" xyz="0 0 0"/>
  </joint>
  <!-- Hip link -->
  <link name="RH_hip_fixed_B">
    <visual>
      <origin rpy="0 0 -3.141592653589793" xyz="0 0 0"/>
      <geometry>
        <mesh filename="../meshes/hip_3_1_1_mesh.dae" scale="1.0 1.0     1.0"/>
      </geometry>
    </visual>
    <inertial>
      <origin rpy="0 0 0" xyz="-0.048 -0.008 -0.003"/>
      <mass value="0.74"/>
      <inertia ixx="0.001393106" ixy="8.4012e-05" ixz="-2.3378e-05" iyy="0.003798579" iyz="-7.1319e-05" izz="0.003897509"/>
    </inertial>
  </link>
  <!-- [rad] -->
  <!-- joint hip HFE -->
  <joint name="RH_hip_fixed_RH_HFE_B" type="fixed">
    <parent link="RH_hip_fixed_B"/>
    <child link="RH_HFE_B"/>
    <origin rpy="0 0 -1.5707963267948966" xyz="-0.0599 -0.08381 0.0"/>
  </joint>
  <!-- [m] -->
  <!-- [A] -->
  <!-- Drive link -->
  <link name="RH_HFE_B">
    <visual>
      <origin rpy="0 0 0" xyz="0 0 0"/>
      <geometry>
        <mesh filename="../meshes/drive_3_0_2_mesh.dae" scale="1.0 1.0     1.0"/>
      </geometry>
    </visual>
    <collision>
      <origin rpy="0 1.5707963267948966 0" xyz="-0.07 0 0"/>
      <geometry>
        <cylinder length="0.14" radius="0.05"/>
      </geometry>
    </collision>
    <inertial>
      <origin rpy="0 0 0" xyz="-0.063 7e-05 0.00046"/>
      <mass value="2.04"/>
      <inertia ixx="0.001053013" ixy="4.527e-05" ixz="8.855e-05" iyy="0.001805509" iyz="9.909e-05" izz="0.001765827"/>
    </inertial>
  </link>
  <!-- joint Drive output -->
  <joint name="RH_HFE_B" type="revolute">
    <parent link="RH_HFE_B"/>
    <child link="RH_THIGH_B"/>
    <origin rpy="0 0 0" xyz="0 0 0"/>
    <axis xyz="-1 0 0"/>
    <limit command_effort="80.0" current="32.0" effort="80.0" gear_velocity="7.5" lower="-9.42477796076938" upper="9.42477796076938" velocity="7.5"/>
    <dynamics damping="0.0" friction="0.0"/>
  </joint>
  <!-- Drive output link -->
  <link name="RH_THIGH_B">
    <inertial>
      <origin rpy="0 0 0" xyz="0 0 0"/>
      <mass value="0.001"/>
      <inertia ixx="0.000001" ixy="0.0" ixz="0.0" iyy="0.000001" iyz="0.0" izz="0.000001"/>
    </inertial>
  </link>
  <!-- [m] -->
  <!-- measured -->
  <!-- joint HFE thigh -->
  <joint name="RH_THIGH_RH_thigh_fixed_B" type="fixed">
    <parent link="RH_THIGH_B"/>
    <child link="RH_thigh_fixed_B"/>
    <origin rpy="0 0 1.5707963267948966" xyz="0 0 0"/>
  </joint>
  <!-- Thigh link -->
  <link name="RH_thigh_fixed_B">
    <visual>
      <origin rpy="0 0 -3.141592653589793" xyz="0 0 0"/>
      <geometry>
        <mesh filename="../meshes/thigh_3_1_1_mesh.dae" scale="1.0 1.0     1.0"/>
      </geometry>
    </visual>
    <!-- Thigh collision -->
    <collision>
      <origin rpy="1.5707963267948966 0 0" xyz="0 -0.04 0"/>
      <geometry>
        <cylinder length="0.08" radius="0.065"/>
      </geometry>
    </collision>
    <collision>
      <origin rpy="0 0 0" xyz="0 -0.03 -0.1413135"/>
      <geometry>
        <box size="0.07500000000000001 0.06 0.282627"/>
      </geometry>
    </collision>
    <inertial>
      <origin rpy="0 0 0" xyz="-0.0 -0.018 -0.169"/>
      <mass value="1.03"/>
      <inertia ixx="0.018644469" ixy="5.2e-08" ixz="-1.0157e-05" iyy="0.019312599" iyz="-0.002520077" izz="0.002838361"/>
    </inertial>
  </link>
  <!-- [rad] -->
  <!-- joint thigh KFE -->
  <joint name="RH_thigh_fixed_RH_KFE_B" type="fixed">
    <parent link="RH_thigh_fixed_B"/>
    <child link="RH_KFE_B"/>
    <origin rpy="0 0 -1.5707963267948966" xyz="-0.0 -0.1003 -0.285"/>
  </joint>
  <!-- [m] -->
  <!-- [A] -->
  <!-- Drive link -->
  <link name="RH_KFE_B">
    <visual>
      <origin rpy="0 0 0" xyz="0 0 0"/>
      <geometry>
        <mesh filename="../meshes/drive_3_0_2_mesh.dae" scale="1.0 1.0     1.0"/>
      </geometry>
    </visual>
    <collision>
      <origin rpy="0 1.5707963267948966 0" xyz="-0.07 0 0"/>
      <geometry>
        <cylinder length="0.14" radius="0.05"/>
      </geometry>
    </collision>
    <inertial>
      <origin rpy="0 0 0" xyz="-0.063 7e-05 0.00046"/>
      <mass value="2.04"/>
      <inertia ixx="0.001053013" ixy="4.527e-05" ixz="8.855e-05" iyy="0.001805509" iyz="9.909e-05" izz="0.001765827"/>
    </inertial>
  </link>
  <!-- joint Drive output -->
  <joint name="RH_KFE_B" type="revolute">
    <parent link="RH_KFE_B"/>
    <child link="RH_SHANK_B"/>
    <origin rpy="0 0 0" xyz="0 0 0"/>
    <axis xyz="-1 0 0"/>
    <limit command_effort="80.0" current="32.0" effort="80.0" gear_velocity="7.5" lower="-9.42477796076938" upper="9.42477796076938" velocity="7.5"/>
    <dynamics damping="0.0" friction="0.0"/>
  </joint>
  <!-- Drive output link -->
  <link name="RH_SHANK_B">
    <inertial>
      <origin rpy="0 0 0" xyz="0 0 0"/>
      <mass value="0.001"/>
      <inertia ixx="0.000001" ixy="0.0" ixz="0.0" iyy="0.000001" iyz="0.0" izz="0.000001"/>
    </inertial>
  </link>
  <!-- [m] -->
  <!-- measured -->
  <!-- joint KFE shank -->
  <joint name="RH_shank_RH_shank_fixed_B" type="fixed">
    <parent link="RH_SHANK_B"/>
    <child link="RH_shank_fixed_B"/>
    <origin rpy="0 0 1.5707963267948966" xyz="0 0 0"/>
  </joint>
  <!-- Shank link -->
  <link name="RH_shank_fixed_B">
    <visual>
      <origin rpy="0 0 -3.141592653589793" xyz="0 0 0"/>
      <geometry>
        <mesh filename="../meshes/shank_3_1_1_mesh.dae" scale="1.0 1.0     1.0"/>
      </geometry>
    </visual>
    <!-- Shank collision -->
    <collision>
      <origin rpy="1.5707963267948966 0 0" xyz="0 -0.02 0"/>
      <geometry>
        <cylinder length="0.04" radius="0.06"/>
      </geometry>
    </collision>
    <collision>
      <origin rpy="1.5707963267948966 0 0" xyz="-0.057499 -0.02 0"/>
      <geometry>
        <box size="0.114998 0.0675 0.04"/>
      </geometry>
    </collision>
    <inertial>
      <origin rpy="0 0 0" xyz="-0.03463 -0.00688 0.00098"/>
      <mass value="0.33742"/>
      <inertia ixx="0.00032748005" ixy="2.142561e-05" ixz="-1.33942e-05" iyy="0.00110974122" iyz="-7.601e-08" izz="0.00089388521"/>
    </inertial>
  </link>
  <!-- Leg configurations: xx (knees bent inwards), xo (knees bent backwards) -->
  <!-- joint shank foot -->
  <joint name="RH_shank_fixed_RH_FOOT_B" type="fixed">
    <parent link="RH_shank_fixed_B"/>
    <child link="RH_FOOT_B"/>
    <origin rpy="0 0 0" xyz="-0.08795 -0.01305 -0.33797"/>
  </joint>
  <!-- Foot link -->
  <link name="RH_FOOT_B">
    <visual>
      <origin rpy="0 0 -3.9269908169872414" xyz="0 0 0"/>
      <geometry>
        <mesh filename="../meshes/foot_3_1_1_mesh.dae" scale="1.0 1.0     1.0"/>
      </geometry>
    </visual>
    <!-- Adapter collision -->
    <collision>
      <origin rpy="0 0 0" xyz="0 0 0.168985"/>
      <geometry>
        <cylinder length="0.282504" radius="0.0175"/>
      </geometry>
    </collision>
    <!-- Foot collision -->
    <collision>
      <origin xyz="0 0 0.0225"/>
      <geometry>
        <sphere radius="0.03"/>
      </geometry>
    </collision>
    <inertial>
      <origin rpy="0 0 0" xyz="-0.00948 0.00948 0.1468"/>
      <mass value="0.25"/>
      <inertia ixx="0.00317174097" ixy="2.63048e-06" ixz="-6.815581e-05" iyy="0.00317174092" iyz="-6.815583e-05" izz="8.319196e-05"/>
    </inertial>
  </link>
  <!-- Gazebo customization -->
  <gazebo reference="RH_FOOT_B">
    <kp>1000000.0</kp>
    <kd>100.0</kd>
    <mu1>0.8</mu1>
    <mu2>0.8</mu2>
  </gazebo>
  <!-- [kg * m^2] -->
  <!-- Fixed joint base hatch -->
  <joint name="base_hatch_B" type="fixed">
    <parent link="base_B"/>
    <child link="hatch_B"/>
    <origin rpy="0 0 0" xyz="0.0 0.0 0.0"/>
  </joint>
  <!-- Hatch link -->
  <link name="hatch_B">
    <visual>
      <origin rpy="0 0 0" xyz="0.116 0 0.073"/>
      <geometry>
        <mesh filename="../meshes/hatch_3_1_1_mesh.dae" scale="1.0 1.0 1.0"/>
      </geometry>
    </visual>
    <inertial>
      <origin rpy="0 0 0" xyz="0.116 0.0 0.0758"/>
      <mass value="0.142"/>
      <inertia ixx="0.001" ixy="0.001" ixz="0.001" iyy="0.001" iyz="0.001" izz="0.001"/>
    </inertial>
  </link>
  <gazebo>
    <plugin filename="libanymal_gazebo.so" name="gazebo_ros_control">
      <robotNamespace>anymal</robotNamespace>
      <!-- Currently unused -->
      <robotDescription>anymal_description</robotDescription>
      <robotBaseLink>base</robotBaseLink>
    </plugin>
  </gazebo>
  <!-- [kg * m^2] -->
  <!-- [m] -->
  <!-- measured -->
  <!-- Base link -->
  <link name="base_A">
    <visual>
      <origin rpy="0 0 0" xyz="0 0 0"/>
      <geometry>
        <mesh filename="../meshes/base_3_1_1_mesh.dae" scale="1.0 1.0     1.0"/>
      </geometry>
    </visual>
    <collision>
      <origin rpy="0 0 0" xyz="0 0 0"/>
      <geometry>
        <box size="0.58 0.14 0.18"/>
      </geometry>
    </collision>
    <collision>
      <origin rpy="0 1.5707963267948966 0" xyz="0.21749999999999997 0.07 0"/>
      <geometry>
        <cylinder length="0.145" radius="0.09"/>
      </geometry>
    </collision>
    <collision>
      <origin rpy="0 1.5707963267948966 0" xyz="-0.21749999999999997 0.07 0"/>
      <geometry>
        <cylinder length="0.145" radius="0.09"/>
      </geometry>
    </collision>
    <collision>
      <origin rpy="0 1.5707963267948966 0" xyz="0.21749999999999997 -0.07 0"/>
      <geometry>
        <cylinder length="0.145" radius="0.09"/>
      </geometry>
    </collision>
    <collision>
      <origin rpy="0 1.5707963267948966 0" xyz="-0.21749999999999997 -0.07 0"/>
      <geometry>
        <cylinder length="0.145" radius="0.09"/>
      </geometry>
    </collision>
    <!-- Shell self filtering -->
    <self_filter>
      <origin rpy="0 0 0" xyz="0 0 0"/>
      <geometry>
        <box size="1.05 0.5 0.5"/>
      </geometry>
    </self_filter>
  </link>
  <!-- Fixed joint to add dummy inertia link -->
  <joint name="base_to_base_inertia_A" type="fixed">
    <parent link="base_A"/>
    <child link="base_inertia_A"/>
    <origin rpy="0 0 0" xyz="0 0 0"/>
  </joint>
  <!-- Dummy inertia link, because KDL cannot have inertia on the base link -->
  <link name="base_inertia_A">
    <inertial>
      <origin rpy="0 0 0" xyz="-0.018 -0.002 0.024"/>
      <mass value="6.222"/>
      <inertia ixx="0.017938806" ixy="0.00387963" ixz="0.001500772" iyy="0.370887745" iyz="6.8963e-05" izz="0.372497653"/>
    </inertial>
  </link>
  <!-- [kg * m^2] -->
  <!-- Fixed joint base topshell -->
  <joint name="base_top_shell_A" type="fixed">
    <parent link="base_A"/>
    <child link="top_shell_A"/>
    <origin rpy="0 0 0" xyz="0 0 0"/>
  </joint>
  <!-- Top shell link -->
  <link name="top_shell_A">
    <visual>
      <origin rpy="0 0 0" xyz="0 0 0"/>
      <geometry>
        <mesh filename="../meshes/top_shell_3_1_1_mesh.dae" scale="1.0 1.0 1.0"/>
      </geometry>
    </visual>
    <inertial>
      <origin rpy="0 0 0" xyz="-0.00777 -0.00013 0.06523"/>
      <mass value="0.534"/>
      <inertia ixx="0.00664789486" ixy="1.247923e-05" ixz="0.00053990097" iyy="0.02587392411" iyz="3.7614e-07" izz="0.03152303792"/>
    </inertial>
  </link>
  <!-- [kg * m^2] -->
  <!-- Fixed joint base topshell -->
  <joint name="base_bottom_shell_A" type="fixed">
    <parent link="base_A"/>
    <child link="bottom_shell_A"/>
    <origin rpy="0 0 0" xyz="0 0 0"/>
  </joint>
  <!-- Bottom shell link -->
  <link name="bottom_shell_A">
    <visual>
      <origin rpy="0 0 0" xyz="0 0 0"/>
      <geometry>
        <mesh filename="../meshes/bottom_shell_3_1_1_mesh.dae" scale="1.0 1.0 1.0"/>
      </geometry>
    </visual>
    <inertial>
      <origin rpy="0 0 0" xyz="-0.00333 1e-05 -0.07705"/>
      <mass value="1.15"/>
      <inertia ixx="0.00927353677" ixy="5.41222e-06" ixz="9.039821e-05" iyy="0.06134388239" iyz="2.3042e-07" izz="0.06853531465"/>
    </inertial>
  </link>
  <!-- [kg * m^2] -->
  <!-- Fixed joint base remote -->
  <joint name="base_remote_A" type="fixed">
    <parent link="base_A"/>
    <child link="remote_A"/>
    <origin rpy="0 0 0" xyz="0 0 0"/>
  </joint>
  <!-- Remote link -->
  <link name="remote_A">
    <visual>
      <origin rpy="0 0 0" xyz="0 0 0"/>
      <geometry>
        <mesh filename="../meshes/remote_3_1_1_mesh.dae" scale="1.0 1.0     1.0"/>
      </geometry>
    </visual>
    <inertial>
      <origin rpy="0 0 0" xyz="-0.171 0.002 0.096"/>
      <mass value="0.3262"/>
      <inertia ixx="0.000528486" ixy="4.547e-05" ixz="1.10327e-05" iyy="0.001165035" iyz="7.4e-07" izz="0.00124026"/>
    </inertial>
  </link>
  <!-- [kg * m^2] -->
  <!-- Fixed joint base handle -->
  <joint name="base_handle_A" type="fixed">
    <parent link="base_A"/>
    <child link="handle_A"/>
    <origin rpy="0 0 0" xyz="0 0 0"/>
  </joint>
  <!-- Handle link -->
  <link name="handle_A">
    <visual>
      <origin rpy="0 0 0" xyz="0 0 0"/>
      <geometry>
        <mesh filename="../meshes/handle_3_1_1_mesh.dae" scale="1.0 1.0     1.0"/>
      </geometry>
    </visual>
    <inertial>
      <origin rpy="0 0 0" xyz="0.37801 0.0 0.1372"/>
      <mass value="0.314"/>
      <inertia ixx="0.001525739" ixy="0.0" ixz="6.272e-05" iyy="0.00071584" iyz="1e-09" izz="0.001164779"/>
    </inertial>
  </link>
  <!-- [m] -->
  <!-- measured -->
  <!-- Fixed joint base face -->
  <joint name="base_face_front_A" type="fixed">
    <parent link="base_A"/>
    <child link="face_front_A"/>
    <origin rpy="0 0 -0.0" xyz="0.4145 0 0"/>
  </joint>
  <!-- Shell link -->
  <link name="face_front_A">
    <visual>
      <origin rpy="0 0 0" xyz="0 0 0"/>
      <geometry>
        <mesh filename="../meshes/face_3_1_1_mesh.dae" scale="1.0 1.0 1.0"/>
      </geometry>
    </visual>
    <collision>
      <origin rpy="0 0 0" xyz="0.055 0 0"/>
      <geometry>
        <box size="0.11 0.14 0.18"/>
      </geometry>
    </collision>
    <collision>
      <origin rpy="0 1.5707963267948966 0" xyz="0.055 0.07 0"/>
      <geometry>
        <cylinder length="0.11" radius="0.09"/>
      </geometry>
    </collision>
    <collision>
      <origin rpy="0 1.5707963267948966 0" xyz="0.055 -0.07 0"/>
      <geometry>
        <cylinder length="0.11" radius="0.09"/>
      </geometry>
    </collision>
    <inertial>
      <origin rpy="0 0 0" xyz="0.042 -0.001 0.004"/>
      <mass value="0.73"/>
      <inertia ixx="0.005238611" ixy="1.7609e-05" ixz="7.2167e-05" iyy="0.002643098" iyz="1.9548e-05" izz="0.004325938"/>
    </inertial>
  </link>
  <!-- [kg * m^2] -->
  <!-- [m] -->
  <!-- Camera joint -->
  <!-- Is located between the two back screw holes at ground level. -->
  <joint name="face_front_A_to_depth_camera_front_A_camera" type="fixed">
    <parent link="face_front_A"/>
    <child link="depth_camera_front_A_camera"/>
    <origin rpy="0.0 0.5235987755982988 0" xyz="0.04715 0.0 -0.0292"/>
  </joint>
  <!-- Camera link -->
  <link name="depth_camera_front_A_camera">
    <visual>
      <origin rpy="0 0 0" xyz="0.0 0.0 0.0"/>
      <geometry>
        <mesh filename="../meshes/realsense_d435_3_1_1_mesh.dae" scale="1.0 1.0 1.0"/>
      </geometry>
    </visual>
    <inertial>
      <origin rpy="0 0 0" xyz="-0.021 -0.002 0.025"/>
      <mass value="0.16043"/>
      <inertia ixx="0.000637051" ixy="0.000484569" ixz="0.000424211" iyy="0.000929402" iyz="5.138e-06" izz="0.000484569"/>
    </inertial>
  </link>
  <!-- Camera parent joint -->
  <!-- Frame lies on the left ir camera according to any_realsense2_camera urdf. -->
  <joint name="depth_camera_front_A_camera_to_camera_parent" type="fixed">
    <parent link="depth_camera_front_A_camera"/>
    <child link="depth_camera_front_A_camera_parent"/>
    <origin rpy="0.0 0.0 0.0" xyz="0.0255 0.0175 0.0"/>
  </joint>
  <!-- Camera parent link -->
  <link name="depth_camera_front_A_camera_parent"/>
  <!-- simulation or bagfile_is_played -->
  <!-- simulation -->
  <!-- [kg * m^2] -->
  <!-- [m] -->
  <!-- Camera joint -->
  <!-- Is located in the center of the mounting points. -->
  <joint name="face_front_A_to_wide_angle_camera_front_A_camera" type="fixed">
    <parent link="face_front_A"/>
    <child link="wide_angle_camera_front_A_camera"/>
    <origin rpy="0 0 0" xyz="0.09850 0.0 0.01497"/>
  </joint>
  <!-- Camera link -->
  <link name="wide_angle_camera_front_A_camera">
    <visual>
      <origin rpy="0 0 0" xyz="0.0 0.0 0.0"/>
      <geometry>
        <mesh filename="../meshes/blackfly_3_1_1_mesh.dae" scale="1.0 1.0 1.0"/>
      </geometry>
    </visual>
    <inertial>
      <origin rpy="0 0 0" xyz="-0.053 -0.001 0.025"/>
      <mass value="0.287"/>
      <inertia ixx="0.000559232" ixy="1.6875e-05" ixz="0.000423761" iyy="0.000946504" iyz="1.3234e-07" izz="0.000493052"/>
    </inertial>
  </link>
  <!-- Camera parent joint -->
  <joint name="wide_angle_camera_front_A_camera_to_camera_parent" type="fixed">
    <parent link="wide_angle_camera_front_A_camera"/>
    <child link="wide_angle_camera_front_A_camera_parent"/>
    <origin rpy="-1.5707963267948966 0.0 -1.5707963267948966" xyz="0.0 0.0 0.0"/>
  </joint>
  <!-- Camera parent link -->
  <link name="wide_angle_camera_front_A_camera_parent"/>
  <!-- simulation -->
  <!-- [m] -->
  <!-- measured -->
  <!-- Fixed joint base face -->
  <joint name="base_face_rear_A" type="fixed">
    <parent link="base_A"/>
    <child link="face_rear_A"/>
    <origin rpy="0 0 3.141592653589793" xyz="-0.4145 0 0"/>
  </joint>
  <!-- Shell link -->
  <link name="face_rear_A">
    <visual>
      <origin rpy="0 0 0" xyz="0 0 0"/>
      <geometry>
        <mesh filename="../meshes/face_3_1_1_mesh.dae" scale="1.0 1.0 1.0"/>
      </geometry>
    </visual>
    <collision>
      <origin rpy="0 0 0" xyz="0.055 0 0"/>
      <geometry>
        <box size="0.11 0.14 0.18"/>
      </geometry>
    </collision>
    <collision>
      <origin rpy="0 1.5707963267948966 0" xyz="0.055 0.07 0"/>
      <geometry>
        <cylinder length="0.11" radius="0.09"/>
      </geometry>
    </collision>
    <collision>
      <origin rpy="0 1.5707963267948966 0" xyz="0.055 -0.07 0"/>
      <geometry>
        <cylinder length="0.11" radius="0.09"/>
      </geometry>
    </collision>
    <inertial>
      <origin rpy="0 0 0" xyz="0.042 -0.001 0.004"/>
      <mass value="0.73"/>
      <inertia ixx="0.005238611" ixy="1.7609e-05" ixz="7.2167e-05" iyy="0.002643098" iyz="1.9548e-05" izz="0.004325938"/>
    </inertial>
  </link>
  <!-- [kg * m^2] -->
  <!-- [m] -->
  <!-- Camera joint -->
  <!-- Is located between the two back screw holes at ground level. -->
  <joint name="face_rear_A_to_depth_camera_rear_A_camera" type="fixed">
    <parent link="face_rear_A"/>
    <child link="depth_camera_rear_A_camera"/>
    <origin rpy="0.0 0.5235987755982988 0" xyz="0.04715 0.0 -0.0292"/>
  </joint>
  <!-- Camera link -->
  <link name="depth_camera_rear_A_camera">
    <visual>
      <origin rpy="0 0 0" xyz="0.0 0.0 0.0"/>
      <geometry>
        <mesh filename="../meshes/realsense_d435_3_1_1_mesh.dae" scale="1.0 1.0 1.0"/>
      </geometry>
    </visual>
    <inertial>
      <origin rpy="0 0 0" xyz="-0.021 -0.002 0.025"/>
      <mass value="0.16043"/>
      <inertia ixx="0.000637051" ixy="0.000484569" ixz="0.000424211" iyy="0.000929402" iyz="5.138e-06" izz="0.000484569"/>
    </inertial>
  </link>
  <!-- Camera parent joint -->
  <!-- Frame lies on the left ir camera according to any_realsense2_camera urdf. -->
  <joint name="depth_camera_rear_A_camera_to_camera_parent" type="fixed">
    <parent link="depth_camera_rear_A_camera"/>
    <child link="depth_camera_rear_A_camera_parent"/>
    <origin rpy="0.0 0.0 0.0" xyz="0.0255 0.0175 0.0"/>
  </joint>
  <!-- Camera parent link -->
  <link name="depth_camera_rear_A_camera_parent"/>
  <!-- simulation or bagfile_is_played -->
  <!-- simulation -->
  <!-- [kg * m^2] -->
  <!-- [m] -->
  <!-- Camera joint -->
  <!-- Is located in the center of the mounting points. -->
  <joint name="face_rear_A_to_wide_angle_camera_rear_A_camera" type="fixed">
    <parent link="face_rear_A"/>
    <child link="wide_angle_camera_rear_A_camera"/>
    <origin rpy="0 0 0" xyz="0.09850 0.0 0.01497"/>
  </joint>
  <!-- Camera link -->
  <link name="wide_angle_camera_rear_A_camera">
    <visual>
      <origin rpy="0 0 0" xyz="0.0 0.0 0.0"/>
      <geometry>
        <mesh filename="../meshes/blackfly_3_1_1_mesh.dae" scale="1.0 1.0 1.0"/>
      </geometry>
    </visual>
    <inertial>
      <origin rpy="0 0 0" xyz="-0.053 -0.001 0.025"/>
      <mass value="0.287"/>
      <inertia ixx="0.000559232" ixy="1.6875e-05" ixz="0.000423761" iyy="0.000946504" iyz="1.3234e-07" izz="0.000493052"/>
    </inertial>
  </link>
  <!-- Camera parent joint -->
  <joint name="wide_angle_camera_rear_A_camera_to_camera_parent" type="fixed">
    <parent link="wide_angle_camera_rear_A_camera"/>
    <child link="wide_angle_camera_rear_A_camera_parent"/>
    <origin rpy="-1.5707963267948966 0.0 -1.5707963267948966" xyz="0.0 0.0 0.0"/>
  </joint>
  <!-- Camera parent link -->
  <link name="wide_angle_camera_rear_A_camera_parent"/>
  <!-- simulation -->
  <!-- [kg * m^2] -->
  <!-- Fixed joint base battery -->
  <joint name="base_battery_A" type="fixed">
    <parent link="base_A"/>
    <child link="battery_A"/>
    <origin rpy="0 0 0" xyz="0 0 0"/>
  </joint>
  <!-- Shell link -->
  <link name="battery_A">
    <visual>
      <origin rpy="0 0 0" xyz="0 0 0"/>
      <geometry>
        <mesh filename="../meshes/battery_3_0_4_mesh.dae" scale="1.0 1.0     1.0"/>
      </geometry>
    </visual>
    <inertial>
      <origin rpy="0 0 0" xyz="-0.00067 -0.00023 -0.03362"/>
      <mass value="5.53425"/>
      <inertia ixx="0.00749474794" ixy="0.00016686282" ixz="7.82763e-05" iyy="0.0722338913" iyz="1.42902e-06" izz="0.07482717535"/>
    </inertial>
  </link>
  <!-- [kg * m^2] -->
  <!-- Fixed joint to add docking  -->
  <joint name="base_to_docking_hatch_cover_A" type="fixed">
    <parent link="base_A"/>
    <child link="docking_hatch_cover_A"/>
    <origin rpy="0 0 0" xyz="0.343 0.0 -0.07"/>
  </joint>
  <!-- Hatch cover link -->
  <link name="docking_hatch_cover_A">
    <!--  TODO(fgiraldez): add visual    -->
    <inertial>
      <origin rpy="0 0 0" xyz="-0.003 0.0 0.005"/>
      <mass value="0.065"/>
      <inertia ixx="0.00063283" ixy="0.0" ixz="3.45e-07" iyy="0.00110971" iyz="0.0" izz="0.00171883"/>
    </inertial>
  </link>
  <!-- [] -->
  <link name="imu_A_link">
    <visual>
      <origin rpy="0 0 0" xyz="0 0 0.005"/>
      <geometry>
        <box size="0.024 0.024 0.01"/>
      </geometry>
      <material name="orange"/>
    </visual>
    <collision>
      <origin rpy="0 0 0" xyz="0 0 0.005"/>
      <geometry>
        <box size="0.024 0.024 0.01"/>
      </geometry>
    </collision>
    <inertial>
      <mass value="0.01"/>
      <origin xyz="0 0 0"/>
      <inertia ixx="5.633333333333334e-07" ixy="0.0" ixz="0.0" iyy="9.6e-07" iyz="0.0" izz="5.633333333333334e-07"/>
    </inertial>
  </link>
  <joint name="imu_A_joint" type="fixed">
    <parent link="base_A"/>
    <child link="imu_A_link"/>
    <origin rpy="0.0 0.0 1.5707963267948966" xyz="0.2488 0.00835 0.04628"/>
  </joint>
  <gazebo reference="imu_A_link">
    <material>Gazebo/Orange</material>
    <mu1>0.8</mu1>
    <mu2>0.8</mu2>
  </gazebo>
  <gazebo reference="imu_A_joint">
      </gazebo>
  <gazebo>
    <plugin filename="libany_hector_gazebo_ros_imu.so" name="imu_A_plugin">
      <robotNamespace>sensors</robotNamespace>
      <bodyName>imu_A_link</bodyName>
      <frameId>imu_link</frameId>
      <topicName>imu</topicName>
      <biasTopicName>imu/bias</biasTopicName>
      <serviceName>imu/calibrate</serviceName>
      <updateRate>400</updateRate>
    </plugin>
  </gazebo>
  <!-- [kg * m^2] -->
  <!-- [m] -->
  <!-- Camera joint -->
  <!-- Is located between the two back screw holes at ground level. -->
  <joint name="base_A_to_depth_camera_left_A_camera" type="fixed">
    <parent link="base_A"/>
    <child link="depth_camera_left_A_camera"/>
    <origin rpy="0.0 0.5235987755982988 1.5707963267948966" xyz="0.0 0.07646 0.02905"/>
  </joint>
  <!-- Camera link -->
  <link name="depth_camera_left_A_camera">
    <visual>
      <origin rpy="0 0 0" xyz="0.0 0.0 0.0"/>
      <geometry>
        <mesh filename="../meshes/realsense_d435_3_1_1_mesh.dae" scale="1.0 1.0 1.0"/>
      </geometry>
    </visual>
    <inertial>
      <origin rpy="0 0 0" xyz="-0.021 -0.002 0.025"/>
      <mass value="0.16043"/>
      <inertia ixx="0.000637051" ixy="0.000484569" ixz="0.000424211" iyy="0.000929402" iyz="5.138e-06" izz="0.000484569"/>
    </inertial>
  </link>
  <!-- Camera parent joint -->
  <!-- Frame lies on the left ir camera according to any_realsense2_camera urdf. -->
  <joint name="depth_camera_left_A_camera_to_camera_parent" type="fixed">
    <parent link="depth_camera_left_A_camera"/>
    <child link="depth_camera_left_A_camera_parent"/>
    <origin rpy="0.0 0.0 0.0" xyz="0.0255 0.0175 0.0"/>
  </joint>
  <!-- Camera parent link -->
  <link name="depth_camera_left_A_camera_parent"/>
  <!-- simulation or bagfile_is_played -->
  <!-- simulation -->
  <!-- [kg * m^2] -->
  <!-- [m] -->
  <!-- Camera joint -->
  <!-- Is located between the two back screw holes at ground level. -->
  <joint name="base_A_to_depth_camera_right_A_camera" type="fixed">
    <parent link="base_A"/>
    <child link="depth_camera_right_A_camera"/>
    <origin rpy="0.0 0.5235987755982988 -1.5707963267948966" xyz="0.0 -0.07646 0.02905"/>
  </joint>
  <!-- Camera link -->
  <link name="depth_camera_right_A_camera">
    <visual>
      <origin rpy="0 0 0" xyz="0.0 0.0 0.0"/>
      <geometry>
        <mesh filename="../meshes/realsense_d435_3_1_1_mesh.dae" scale="1.0 1.0 1.0"/>
      </geometry>
    </visual>
    <inertial>
      <origin rpy="0 0 0" xyz="-0.021 -0.002 0.025"/>
      <mass value="0.16043"/>
      <inertia ixx="0.000637051" ixy="0.000484569" ixz="0.000424211" iyy="0.000929402" iyz="5.138e-06" izz="0.000484569"/>
    </inertial>
  </link>
  <!-- Camera parent joint -->
  <!-- Frame lies on the left ir camera according to any_realsense2_camera urdf. -->
  <joint name="depth_camera_right_A_camera_to_camera_parent" type="fixed">
    <parent link="depth_camera_right_A_camera"/>
    <child link="depth_camera_right_A_camera_parent"/>
    <origin rpy="0.0 0.0 0.0" xyz="0.0255 0.0175 0.0"/>
  </joint>
  <!-- Camera parent link -->
  <link name="depth_camera_right_A_camera_parent"/>
  <!-- simulation or bagfile_is_played -->
  <!-- simulation -->
  <!-- [kg * m^2] -->
  <!-- [m] -->
  <!-- parent to cage joint, located between mounting plate on trunk and the cage -->
  <joint name="base_A_to_lidar_A_cage" type="fixed">
    <parent link="base_A"/>
    <child link="lidar_A_cage"/>
    <origin rpy="0 0 0" xyz="-0.364 0.0 0.0735"/>
  </joint>
  <!-- Velodyne cage link -->
  <link name="lidar_A_cage">
    <visual>
      <origin rpy="0.0 0.0 0.0" xyz="0.0 0.0 0.0"/>
      <geometry>
        <mesh filename="../meshes/cage_3_1_1_mesh.dae" scale="1.0 1.0 1.0"/>
      </geometry>
    </visual>
    <collision>
      <origin rpy="0 0 0" xyz="0 0 0.06"/>
      <geometry>
        <cylinder length="0.12" radius="0.07"/>
      </geometry>
    </collision>
    <inertial>
      <origin rpy="0.0 0.0 0.0" xyz="0.002 0.0 0.099"/>
      <mass value="0.545"/>
      <inertia ixx="0.003156254" ixy="0.0" ixz="1.0992e-05" iyy="0.002357216" iyz="0.0" izz="0.001326455"/>
    </inertial>
  </link>
  <!-- [kg * m^2] -->
  <!-- parent to sensor joint -->
  <joint name="lidar_A_cage_to_lidar_A" type="fixed">
    <parent link="lidar_A_cage"/>
    <child link="lidar_A"/>
    <origin rpy="0.0 0.0 -1.5707963267948966" xyz="0.0 0.0 0.0687"/>
  </joint>
  <!-- Velodyne sensor link -->
  <link name="lidar_A">
    <inertial>
      <origin rpy="0.0 0.0 0.0" xyz="-0.012 0.001 -0.008"/>
      <mass value="0.695"/>
      <inertia ixx="0.000846765" ixy="6.9565e-05" ixz="0.00027111" iyy="0.001367583" iyz="5.8984e-05" izz="0.001363673"/>
    </inertial>
    <visual>
      <origin xyz="0 0 0"/>
      <geometry>
        <mesh filename="../meshes/velodyne_3_1_1_mesh.dae"/>
      </geometry>
    </visual>
  </link>
  <!-- simulation -->
  <joint name="base_A_to_linkage" type="fixed">
    <parent link="base_link"/>
    <child link="base_A"/>
    <origin rpy="0 0 1.57079633" xyz="-0.6 0 -0.35"/>
  </joint>
  <!--xacro:if value="${version_ != 'c100'}">
      <xacro:include filename="$(find anymal_c)/urdf/base/base_3_0_macro.urdf.xacro"/>
      <xacro:base fix_base="$(arg fix_base)"
                  simulate_depth_camera="$(arg simulate_depth_camera)"
                  simulate_lidar="$(arg simulate_lidar)"
                  simulate_wide_angle_camera="$(arg simulate_wide_angle_camera)"
                  version="${version_}"
                  depth_camera_front_roll="$(arg depth_camera_front_roll)"
                  depth_camera_front_pitch="$(arg depth_camera_front_pitch)"
                  depth_camera_rear_roll="$(arg depth_camera_rear_roll)"
                  depth_camera_rear_pitch="$(arg depth_camera_rear_pitch)"
                  depth_camera_left_roll="$(arg depth_camera_left_roll)"
                  depth_camera_left_pitch="$(arg depth_camera_left_pitch)"
                  depth_camera_right_roll="$(arg depth_camera_right_roll)"
                  depth_camera_right_pitch="$(arg depth_camera_right_pitch)"
                  imu_model="$(arg imu_model)"
                  imu_roll="$(arg imu_roll)"
                  imu_pitch="$(arg imu_pitch)"
                  imu_yaw="$(arg imu_yaw)"
                  battery_model="$(arg battery_model)"
                  docking_socket="$(arg docking_socket)"
                  m_B="$(arg m_B)"
                  B_r_BBcom_x="$(arg B_r_BBcom_x)"
                  B_r_BBcom_y="$(arg B_r_BBcom_y)"
                  B_r_BBcom_z="$(arg B_r_BBcom_z)"/>
    </xacro:if-->
  <!-- Legs -->
  <!--xacro:if value="${version_ == 'c010'}">
      <xacro:include filename="$(find anymal_c)/urdf/leg/leg_3_0_macro.urdf.xacro"/>
    </xacro:if>

    <xacro:if value="${version_ == 'c020'}">
      <xacro:include filename="$(find anymal_c)/urdf/leg/leg_3_0_1_macro.urdf.xacro"/>
    </xacro:if-->
  <!-- [rad] -->
  <!-- [rad] -->
  <!-- joint base HAA -->
  <joint name="base_LF_HAA_A" type="fixed">
    <parent link="base_A"/>
    <child link="LF_HAA_A"/>
    <origin rpy="2.6179938779914944 0 0.0" xyz="0.2999 0.104 0.0"/>
  </joint>
  <!-- [m] -->
  <!-- [A] -->
  <!-- Drive link -->
  <link name="LF_HAA_A">
    <visual>
      <origin rpy="0 0 0" xyz="0 0 0"/>
      <geometry>
        <mesh filename="../meshes/drive_3_0_2_mesh.dae" scale="1.0 1.0     1.0"/>
      </geometry>
    </visual>
    <inertial>
      <origin rpy="0 0 0" xyz="-0.063 7e-05 0.00046"/>
      <mass value="2.04"/>
      <inertia ixx="0.001053013" ixy="4.527e-05" ixz="8.855e-05" iyy="0.001805509" iyz="9.909e-05" izz="0.001765827"/>
    </inertial>
  </link>
  <!-- joint Drive output -->
  <joint name="LF_HAA_A" type="revolute">
    <parent link="LF_HAA_A"/>
    <child link="LF_HIP_A"/>
    <origin rpy="0 0 0" xyz="0 0 0"/>
    <axis xyz="1 0 0"/>
    <limit command_effort="80.0" current="32.0" effort="80.0" gear_velocity="7.5" lower="-0.72" upper="0.49" velocity="7.5"/>
    <dynamics damping="0.0" friction="0.0"/>
  </joint>
  <!-- Drive output link -->
  <link name="LF_HIP_A">
    <inertial>
      <origin rpy="0 0 0" xyz="0 0 0"/>
      <mass value="0.001"/>
      <inertia ixx="0.000001" ixy="0.0" ixz="0.0" iyy="0.000001" iyz="0.0" izz="0.000001"/>
    </inertial>
  </link>
  <!-- [kg * m^2] -->
  <!-- joint HAA hip -->
  <joint name="LF_HIP_LF_hip_fixed_A" type="fixed">
    <parent link="LF_HIP_A"/>
    <child link="LF_hip_fixed_A"/>
    <origin rpy="-2.6179938779914944 0 0.0" xyz="0 0 0"/>
  </joint>
  <!-- Hip link -->
  <link name="LF_hip_fixed_A">
    <visual>
      <origin rpy="0 0 0.0" xyz="0 0 0"/>
      <geometry>
        <mesh filename="../meshes/hip_3_1_1_mesh.dae" scale="1.0 1.0     1.0"/>
      </geometry>
    </visual>
    <inertial>
      <origin rpy="0 0 0" xyz="0.048 0.008 -0.003"/>
      <mass value="0.74"/>
      <inertia ixx="0.001393106" ixy="8.4012e-05" ixz="2.3378e-05" iyy="0.003798579" iyz="7.1319e-05" izz="0.003897509"/>
    </inertial>
  </link>
  <!-- [rad] -->
  <!-- joint hip HFE -->
  <joint name="LF_hip_fixed_LF_HFE_A" type="fixed">
    <parent link="LF_hip_fixed_A"/>
    <child link="LF_HFE_A"/>
    <origin rpy="0 0 1.5707963267948966" xyz="0.0599 0.08381 0.0"/>
  </joint>
  <!-- [m] -->
  <!-- [A] -->
  <!-- Drive link -->
  <link name="LF_HFE_A">
    <visual>
      <origin rpy="0 0 0" xyz="0 0 0"/>
      <geometry>
        <mesh filename="../meshes/drive_3_0_2_mesh.dae" scale="1.0 1.0     1.0"/>
      </geometry>
    </visual>
    <collision>
      <origin rpy="0 1.5707963267948966 0" xyz="-0.07 0 0"/>
      <geometry>
        <cylinder length="0.14" radius="0.05"/>
      </geometry>
    </collision>
    <inertial>
      <origin rpy="0 0 0" xyz="-0.063 7e-05 0.00046"/>
      <mass value="2.04"/>
      <inertia ixx="0.001053013" ixy="4.527e-05" ixz="8.855e-05" iyy="0.001805509" iyz="9.909e-05" izz="0.001765827"/>
    </inertial>
  </link>
  <!-- joint Drive output -->
  <joint name="LF_HFE_A" type="revolute">
    <parent link="LF_HFE_A"/>
    <child link="LF_THIGH_A"/>
    <origin rpy="0 0 0" xyz="0 0 0"/>
    <axis xyz="1 0 0"/>
    <limit command_effort="80.0" current="32.0" effort="80.0" gear_velocity="7.5" lower="-9.42477796076938" upper="9.42477796076938" velocity="7.5"/>
    <dynamics damping="0.0" friction="0.0"/>
  </joint>
  <!-- Drive output link -->
  <link name="LF_THIGH_A">
    <inertial>
      <origin rpy="0 0 0" xyz="0 0 0"/>
      <mass value="0.001"/>
      <inertia ixx="0.000001" ixy="0.0" ixz="0.0" iyy="0.000001" iyz="0.0" izz="0.000001"/>
    </inertial>
  </link>
  <!-- [m] -->
  <!-- measured -->
  <!-- joint HFE thigh -->
  <joint name="LF_THIGH_LF_thigh_fixed_A" type="fixed">
    <parent link="LF_THIGH_A"/>
    <child link="LF_thigh_fixed_A"/>
    <origin rpy="0 0 -1.5707963267948966" xyz="0 0 0"/>
  </joint>
  <!-- Thigh link -->
  <link name="LF_thigh_fixed_A">
    <visual>
      <origin rpy="0 0 0.0" xyz="0 0 0"/>
      <geometry>
        <mesh filename="../meshes/thigh_3_1_1_mesh.dae" scale="1.0 1.0     1.0"/>
      </geometry>
    </visual>
    <!-- Thigh collision -->
    <collision>
      <origin rpy="1.5707963267948966 0 0" xyz="0 0.04 0"/>
      <geometry>
        <cylinder length="0.08" radius="0.065"/>
      </geometry>
    </collision>
    <collision>
      <origin rpy="0 0 0" xyz="0 0.03 -0.1413135"/>
      <geometry>
        <box size="0.07500000000000001 0.06 0.282627"/>
      </geometry>
    </collision>
    <inertial>
      <origin rpy="0 0 0" xyz="0.0 0.018 -0.169"/>
      <mass value="1.03"/>
      <inertia ixx="0.018644469" ixy="5.2e-08" ixz="1.0157e-05" iyy="0.019312599" iyz="0.002520077" izz="0.002838361"/>
    </inertial>
  </link>
  <!-- [rad] -->
  <!-- joint thigh KFE -->
  <joint name="LF_thigh_fixed_LF_KFE_A" type="fixed">
    <parent link="LF_thigh_fixed_A"/>
    <child link="LF_KFE_A"/>
    <origin rpy="0 0 1.5707963267948966" xyz="0.0 0.1003 -0.285"/>
  </joint>
  <!-- [m] -->
  <!-- [A] -->
  <!-- Drive link -->
  <link name="LF_KFE_A">
    <visual>
      <origin rpy="0 0 0" xyz="0 0 0"/>
      <geometry>
        <mesh filename="../meshes/drive_3_0_2_mesh.dae" scale="1.0 1.0     1.0"/>
      </geometry>
    </visual>
    <collision>
      <origin rpy="0 1.5707963267948966 0" xyz="-0.07 0 0"/>
      <geometry>
        <cylinder length="0.14" radius="0.05"/>
      </geometry>
    </collision>
    <inertial>
      <origin rpy="0 0 0" xyz="-0.063 7e-05 0.00046"/>
      <mass value="2.04"/>
      <inertia ixx="0.001053013" ixy="4.527e-05" ixz="8.855e-05" iyy="0.001805509" iyz="9.909e-05" izz="0.001765827"/>
    </inertial>
  </link>
  <!-- joint Drive output -->
  <joint name="LF_KFE_A" type="revolute">
    <parent link="LF_KFE_A"/>
    <child link="LF_SHANK_A"/>
    <origin rpy="0 0 0" xyz="0 0 0"/>
    <axis xyz="1 0 0"/>
    <limit command_effort="80.0" current="32.0" effort="80.0" gear_velocity="7.5" lower="-9.42477796076938" upper="9.42477796076938" velocity="7.5"/>
    <dynamics damping="0.0" friction="0.0"/>
  </joint>
  <!-- Drive output link -->
  <link name="LF_SHANK_A">
    <inertial>
      <origin rpy="0 0 0" xyz="0 0 0"/>
      <mass value="0.001"/>
      <inertia ixx="0.000001" ixy="0.0" ixz="0.0" iyy="0.000001" iyz="0.0" izz="0.000001"/>
    </inertial>
  </link>
  <!-- [m] -->
  <!-- measured -->
  <!-- joint KFE shank -->
  <joint name="LF_shank_LF_shank_fixed_A" type="fixed">
    <parent link="LF_SHANK_A"/>
    <child link="LF_shank_fixed_A"/>
    <origin rpy="0 0 -1.5707963267948966" xyz="0 0 0"/>
  </joint>
  <!-- Shank link -->
  <link name="LF_shank_fixed_A">
    <visual>
      <origin rpy="0 0 0.0" xyz="0 0 0"/>
      <geometry>
        <mesh filename="../meshes/shank_3_1_1_mesh.dae" scale="1.0 1.0     1.0"/>
      </geometry>
    </visual>
    <!-- Shank collision -->
    <collision>
      <origin rpy="1.5707963267948966 0 0" xyz="0 0.02 0"/>
      <geometry>
        <cylinder length="0.04" radius="0.06"/>
      </geometry>
    </collision>
    <collision>
      <origin rpy="1.5707963267948966 0 0" xyz="0.057499 0.02 0"/>
      <geometry>
        <box size="0.114998 0.0675 0.04"/>
      </geometry>
    </collision>
    <inertial>
      <origin rpy="0 0 0" xyz="0.03463 0.00688 0.00098"/>
      <mass value="0.33742"/>
      <inertia ixx="0.00032748005" ixy="2.142561e-05" ixz="1.33942e-05" iyy="0.00110974122" iyz="7.601e-08" izz="0.00089388521"/>
    </inertial>
  </link>
  <!-- Leg configurations: xx (knees bent inwards), xo (knees bent backwards) -->
  <!-- joint shank foot -->
  <joint name="LF_shank_fixed_LF_FOOT_A" type="fixed">
    <parent link="LF_shank_fixed_A"/>
    <child link="LF_FOOT_A"/>
    <origin rpy="0 0 0" xyz="0.08795 0.01305 -0.33797"/>
  </joint>
  <!-- Foot link -->
  <link name="LF_FOOT_A">
    <visual>
      <origin rpy="0 0 -0.7853981633974483" xyz="0 0 0"/>
      <geometry>
        <mesh filename="../meshes/foot_3_1_1_mesh.dae" scale="1.0 1.0     1.0"/>
      </geometry>
    </visual>
    <!-- Adapter collision -->
    <collision>
      <origin rpy="0 0 0" xyz="0 0 0.168985"/>
      <geometry>
        <cylinder length="0.282504" radius="0.0175"/>
      </geometry>
    </collision>
    <!-- Foot collision -->
    <collision>
      <origin xyz="0 0 0.0225"/>
      <geometry>
        <sphere radius="0.03"/>
      </geometry>
    </collision>
    <inertial>
      <origin rpy="0 0 0" xyz="0.00948 -0.00948 0.1468"/>
      <mass value="0.25"/>
      <inertia ixx="0.00317174097" ixy="2.63048e-06" ixz="6.815581e-05" iyy="0.00317174092" iyz="6.815583e-05" izz="8.319196e-05"/>
    </inertial>
  </link>
  <!-- Gazebo customization -->
  <gazebo reference="LF_FOOT_A">
    <kp>1000000.0</kp>
    <kd>100.0</kd>
    <mu1>0.8</mu1>
    <mu2>0.8</mu2>
  </gazebo>
  <!-- [rad] -->
  <!-- [rad] -->
  <!-- joint base HAA -->
  <joint name="base_RF_HAA_A" type="fixed">
    <parent link="base_A"/>
    <child link="RF_HAA_A"/>
    <origin rpy="-2.6179938779914944 0 0.0" xyz="0.2999 -0.104 0.0"/>
  </joint>
  <!-- [m] -->
  <!-- [A] -->
  <!-- Drive link -->
  <link name="RF_HAA_A">
    <visual>
      <origin rpy="0 0 0" xyz="0 0 0"/>
      <geometry>
        <mesh filename="../meshes/drive_3_0_2_mesh.dae" scale="1.0 1.0     1.0"/>
      </geometry>
    </visual>
    <inertial>
      <origin rpy="0 0 0" xyz="-0.063 7e-05 0.00046"/>
      <mass value="2.04"/>
      <inertia ixx="0.001053013" ixy="4.527e-05" ixz="8.855e-05" iyy="0.001805509" iyz="9.909e-05" izz="0.001765827"/>
    </inertial>
  </link>
  <!-- joint Drive output -->
  <joint name="RF_HAA_A" type="revolute">
    <parent link="RF_HAA_A"/>
    <child link="RF_HIP_A"/>
    <origin rpy="0 0 0" xyz="0 0 0"/>
    <axis xyz="1 0 0"/>
    <limit command_effort="80.0" current="32.0" effort="80.0" gear_velocity="7.5" lower="-0.49" upper="0.72" velocity="7.5"/>
    <dynamics damping="0.0" friction="0.0"/>
  </joint>
  <!-- Drive output link -->
  <link name="RF_HIP_A">
    <inertial>
      <origin rpy="0 0 0" xyz="0 0 0"/>
      <mass value="0.001"/>
      <inertia ixx="0.000001" ixy="0.0" ixz="0.0" iyy="0.000001" iyz="0.0" izz="0.000001"/>
    </inertial>
  </link>
  <!-- [kg * m^2] -->
  <!-- joint HAA hip -->
  <joint name="RF_HIP_RF_hip_fixed_A" type="fixed">
    <parent link="RF_HIP_A"/>
    <child link="RF_hip_fixed_A"/>
    <origin rpy="2.6179938779914944 0 0.0" xyz="0 0 0"/>
  </joint>
  <!-- Hip link -->
  <link name="RF_hip_fixed_A">
    <visual>
      <origin rpy="0 0 0.0" xyz="0 0 0"/>
      <geometry>
        <mesh filename="../meshes/hip_3_1_1_mesh_mirrored.dae" scale="1.0 1.0     1.0"/>
      </geometry>
    </visual>
    <inertial>
      <origin rpy="0 0 0" xyz="0.048 -0.008 -0.003"/>
      <mass value="0.74"/>
      <inertia ixx="0.001393106" ixy="-8.4012e-05" ixz="2.3378e-05" iyy="0.003798579" iyz="-7.1319e-05" izz="0.003897509"/>
    </inertial>
  </link>
  <!-- [rad] -->
  <!-- joint hip HFE -->
  <joint name="RF_hip_fixed_RF_HFE_A" type="fixed">
    <parent link="RF_hip_fixed_A"/>
    <child link="RF_HFE_A"/>
    <origin rpy="0 0 -1.5707963267948966" xyz="0.0599 -0.08381 0.0"/>
  </joint>
  <!-- [m] -->
  <!-- [A] -->
  <!-- Drive link -->
  <link name="RF_HFE_A">
    <visual>
      <origin rpy="0 0 0" xyz="0 0 0"/>
      <geometry>
        <mesh filename="../meshes/drive_3_0_2_mesh.dae" scale="1.0 1.0     1.0"/>
      </geometry>
    </visual>
    <collision>
      <origin rpy="0 1.5707963267948966 0" xyz="-0.07 0 0"/>
      <geometry>
        <cylinder length="0.14" radius="0.05"/>
      </geometry>
    </collision>
    <inertial>
      <origin rpy="0 0 0" xyz="-0.063 7e-05 0.00046"/>
      <mass value="2.04"/>
      <inertia ixx="0.001053013" ixy="4.527e-05" ixz="8.855e-05" iyy="0.001805509" iyz="9.909e-05" izz="0.001765827"/>
    </inertial>
  </link>
  <!-- joint Drive output -->
  <joint name="RF_HFE_A" type="revolute">
    <parent link="RF_HFE_A"/>
    <child link="RF_THIGH_A"/>
    <origin rpy="0 0 0" xyz="0 0 0"/>
    <axis xyz="-1 0 0"/>
    <limit command_effort="80.0" current="32.0" effort="80.0" gear_velocity="7.5" lower="-9.42477796076938" upper="9.42477796076938" velocity="7.5"/>
    <dynamics damping="0.0" friction="0.0"/>
  </joint>
  <!-- Drive output link -->
  <link name="RF_THIGH_A">
    <inertial>
      <origin rpy="0 0 0" xyz="0 0 0"/>
      <mass value="0.001"/>
      <inertia ixx="0.000001" ixy="0.0" ixz="0.0" iyy="0.000001" iyz="0.0" izz="0.000001"/>
    </inertial>
  </link>
  <!-- [m] -->
  <!-- measured -->
  <!-- joint HFE thigh -->
  <joint name="RF_THIGH_RF_thigh_fixed_A" type="fixed">
    <parent link="RF_THIGH_A"/>
    <child link="RF_thigh_fixed_A"/>
    <origin rpy="0 0 1.5707963267948966" xyz="0 0 0"/>
  </joint>
  <!-- Thigh link -->
  <link name="RF_thigh_fixed_A">
    <visual>
      <origin rpy="0 0 -3.141592653589793" xyz="0 0 0"/>
      <geometry>
        <mesh filename="../meshes/thigh_3_1_1_mesh.dae" scale="1.0 1.0     1.0"/>
      </geometry>
    </visual>
    <!-- Thigh collision -->
    <collision>
      <origin rpy="1.5707963267948966 0 0" xyz="0 -0.04 0"/>
      <geometry>
        <cylinder length="0.08" radius="0.065"/>
      </geometry>
    </collision>
    <collision>
      <origin rpy="0 0 0" xyz="0 -0.03 -0.1413135"/>
      <geometry>
        <box size="0.07500000000000001 0.06 0.282627"/>
      </geometry>
    </collision>
    <inertial>
      <origin rpy="0 0 0" xyz="0.0 -0.018 -0.169"/>
      <mass value="1.03"/>
      <inertia ixx="0.018644469" ixy="-5.2e-08" ixz="1.0157e-05" iyy="0.019312599" iyz="-0.002520077" izz="0.002838361"/>
    </inertial>
  </link>
  <!-- [rad] -->
  <!-- joint thigh KFE -->
  <joint name="RF_thigh_fixed_RF_KFE_A" type="fixed">
    <parent link="RF_thigh_fixed_A"/>
    <child link="RF_KFE_A"/>
    <origin rpy="0 0 -1.5707963267948966" xyz="0.0 -0.1003 -0.285"/>
  </joint>
  <!-- [m] -->
  <!-- [A] -->
  <!-- Drive link -->
  <link name="RF_KFE_A">
    <visual>
      <origin rpy="0 0 0" xyz="0 0 0"/>
      <geometry>
        <mesh filename="../meshes/drive_3_0_2_mesh.dae" scale="1.0 1.0     1.0"/>
      </geometry>
    </visual>
    <collision>
      <origin rpy="0 1.5707963267948966 0" xyz="-0.07 0 0"/>
      <geometry>
        <cylinder length="0.14" radius="0.05"/>
      </geometry>
    </collision>
    <inertial>
      <origin rpy="0 0 0" xyz="-0.063 7e-05 0.00046"/>
      <mass value="2.04"/>
      <inertia ixx="0.001053013" ixy="4.527e-05" ixz="8.855e-05" iyy="0.001805509" iyz="9.909e-05" izz="0.001765827"/>
    </inertial>
  </link>
  <!-- joint Drive output -->
  <joint name="RF_KFE_A" type="revolute">
    <parent link="RF_KFE_A"/>
    <child link="RF_SHANK_A"/>
    <origin rpy="0 0 0" xyz="0 0 0"/>
    <axis xyz="-1 0 0"/>
    <limit command_effort="80.0" current="32.0" effort="80.0" gear_velocity="7.5" lower="-9.42477796076938" upper="9.42477796076938" velocity="7.5"/>
    <dynamics damping="0.0" friction="0.0"/>
  </joint>
  <!-- Drive output link -->
  <link name="RF_SHANK_A">
    <inertial>
      <origin rpy="0 0 0" xyz="0 0 0"/>
      <mass value="0.001"/>
      <inertia ixx="0.000001" ixy="0.0" ixz="0.0" iyy="0.000001" iyz="0.0" izz="0.000001"/>
    </inertial>
  </link>
  <!-- [m] -->
  <!-- measured -->
  <!-- joint KFE shank -->
  <joint name="RF_shank_RF_shank_fixed_A" type="fixed">
    <parent link="RF_SHANK_A"/>
    <child link="RF_shank_fixed_A"/>
    <origin rpy="0 0 1.5707963267948966" xyz="0 0 0"/>
  </joint>
  <!-- Shank link -->
  <link name="RF_shank_fixed_A">
    <visual>
      <origin rpy="0 0 0.0" xyz="0 0 0"/>
      <geometry>
        <mesh filename="../meshes/shank_3_1_1_mesh_mirrored.dae" scale="1.0 1.0     1.0"/>
      </geometry>
    </visual>
    <!-- Shank collision -->
    <collision>
      <origin rpy="1.5707963267948966 0 0" xyz="0 -0.02 0"/>
      <geometry>
        <cylinder length="0.04" radius="0.06"/>
      </geometry>
    </collision>
    <collision>
      <origin rpy="1.5707963267948966 0 0" xyz="0.057499 -0.02 0"/>
      <geometry>
        <box size="0.114998 0.0675 0.04"/>
      </geometry>
    </collision>
    <inertial>
      <origin rpy="0 0 0" xyz="0.03463 -0.00688 0.00098"/>
      <mass value="0.33742"/>
      <inertia ixx="0.00032748005" ixy="-2.142561e-05" ixz="1.33942e-05" iyy="0.00110974122" iyz="-7.601e-08" izz="0.00089388521"/>
    </inertial>
  </link>
  <!-- Leg configurations: xx (knees bent inwards), xo (knees bent backwards) -->
  <!-- joint shank foot -->
  <joint name="RF_shank_fixed_RF_FOOT_A" type="fixed">
    <parent link="RF_shank_fixed_A"/>
    <child link="RF_FOOT_A"/>
    <origin rpy="0 0 0" xyz="0.08795 -0.01305 -0.33797"/>
  </joint>
  <!-- Foot link -->
  <link name="RF_FOOT_A">
    <visual>
      <origin rpy="0 0 0.7853981633974483" xyz="0 0 0"/>
      <geometry>
        <mesh filename="../meshes/foot_3_1_1_mesh.dae" scale="1.0 1.0     1.0"/>
      </geometry>
    </visual>
    <!-- Adapter collision -->
    <collision>
      <origin rpy="0 0 0" xyz="0 0 0.168985"/>
      <geometry>
        <cylinder length="0.282504" radius="0.0175"/>
      </geometry>
    </collision>
    <!-- Foot collision -->
    <collision>
      <origin xyz="0 0 0.0225"/>
      <geometry>
        <sphere radius="0.03"/>
      </geometry>
    </collision>
    <inertial>
      <origin rpy="0 0 0" xyz="0.00948 0.00948 0.1468"/>
      <mass value="0.25"/>
      <inertia ixx="0.00317174097" ixy="-2.63048e-06" ixz="6.815581e-05" iyy="0.00317174092" iyz="-6.815583e-05" izz="8.319196e-05"/>
    </inertial>
  </link>
  <!-- Gazebo customization -->
  <gazebo reference="RF_FOOT_A">
    <kp>1000000.0</kp>
    <kd>100.0</kd>
    <mu1>0.8</mu1>
    <mu2>0.8</mu2>
  </gazebo>
  <!-- [rad] -->
  <!-- [rad] -->
  <!-- joint base HAA -->
  <joint name="base_LH_HAA_A" type="fixed">
    <parent link="base_A"/>
    <child link="LH_HAA_A"/>
    <origin rpy="-2.6179938779914944 0 -3.141592653589793" xyz="-0.2999 0.104 0.0"/>
  </joint>
  <!-- [m] -->
  <!-- [A] -->
  <!-- Drive link -->
  <link name="LH_HAA_A">
    <visual>
      <origin rpy="0 0 0" xyz="0 0 0"/>
      <geometry>
        <mesh filename="../meshes/drive_3_0_2_mesh.dae" scale="1.0 1.0     1.0"/>
      </geometry>
    </visual>
    <inertial>
      <origin rpy="0 0 0" xyz="-0.063 7e-05 0.00046"/>
      <mass value="2.04"/>
      <inertia ixx="0.001053013" ixy="4.527e-05" ixz="8.855e-05" iyy="0.001805509" iyz="9.909e-05" izz="0.001765827"/>
    </inertial>
  </link>
  <!-- joint Drive output -->
  <joint name="LH_HAA_A" type="revolute">
    <parent link="LH_HAA_A"/>
    <child link="LH_HIP_A"/>
    <origin rpy="0 0 0" xyz="0 0 0"/>
    <axis xyz="-1 0 0"/>
    <limit command_effort="80.0" current="32.0" effort="80.0" gear_velocity="7.5" lower="-0.72" upper="0.49" velocity="7.5"/>
    <dynamics damping="0.0" friction="0.0"/>
  </joint>
  <!-- Drive output link -->
  <link name="LH_HIP_A">
    <inertial>
      <origin rpy="0 0 0" xyz="0 0 0"/>
      <mass value="0.001"/>
      <inertia ixx="0.000001" ixy="0.0" ixz="0.0" iyy="0.000001" iyz="0.0" izz="0.000001"/>
    </inertial>
  </link>
  <!-- [kg * m^2] -->
  <!-- joint HAA hip -->
  <joint name="LH_HIP_LH_hip_fixed_A" type="fixed">
    <parent link="LH_HIP_A"/>
    <child link="LH_hip_fixed_A"/>
    <origin rpy="-2.6179938779914944 0 -3.141592653589793" xyz="0 0 0"/>
  </joint>
  <!-- Hip link -->
  <link name="LH_hip_fixed_A">
    <visual>
      <origin rpy="0 0 -3.141592653589793" xyz="0 0 0"/>
      <geometry>
        <mesh filename="../meshes/hip_3_1_1_mesh_mirrored.dae" scale="1.0 1.0     1.0"/>
      </geometry>
    </visual>
    <inertial>
      <origin rpy="0 0 0" xyz="-0.048 0.008 -0.003"/>
      <mass value="0.74"/>
      <inertia ixx="0.001393106" ixy="-8.4012e-05" ixz="-2.3378e-05" iyy="0.003798579" iyz="7.1319e-05" izz="0.003897509"/>
    </inertial>
  </link>
  <!-- [rad] -->
  <!-- joint hip HFE -->
  <joint name="LH_hip_fixed_LH_HFE_A" type="fixed">
    <parent link="LH_hip_fixed_A"/>
    <child link="LH_HFE_A"/>
    <origin rpy="0 0 1.5707963267948966" xyz="-0.0599 0.08381 0.0"/>
  </joint>
  <!-- [m] -->
  <!-- [A] -->
  <!-- Drive link -->
  <link name="LH_HFE_A">
    <visual>
      <origin rpy="0 0 0" xyz="0 0 0"/>
      <geometry>
        <mesh filename="../meshes/drive_3_0_2_mesh.dae" scale="1.0 1.0     1.0"/>
      </geometry>
    </visual>
    <collision>
      <origin rpy="0 1.5707963267948966 0" xyz="-0.07 0 0"/>
      <geometry>
        <cylinder length="0.14" radius="0.05"/>
      </geometry>
    </collision>
    <inertial>
      <origin rpy="0 0 0" xyz="-0.063 7e-05 0.00046"/>
      <mass value="2.04"/>
      <inertia ixx="0.001053013" ixy="4.527e-05" ixz="8.855e-05" iyy="0.001805509" iyz="9.909e-05" izz="0.001765827"/>
    </inertial>
  </link>
  <!-- joint Drive output -->
  <joint name="LH_HFE_A" type="revolute">
    <parent link="LH_HFE_A"/>
    <child link="LH_THIGH_A"/>
    <origin rpy="0 0 0" xyz="0 0 0"/>
    <axis xyz="1 0 0"/>
    <limit command_effort="80.0" current="32.0" effort="80.0" gear_velocity="7.5" lower="-9.42477796076938" upper="9.42477796076938" velocity="7.5"/>
    <dynamics damping="0.0" friction="0.0"/>
  </joint>
  <!-- Drive output link -->
  <link name="LH_THIGH_A">
    <inertial>
      <origin rpy="0 0 0" xyz="0 0 0"/>
      <mass value="0.001"/>
      <inertia ixx="0.000001" ixy="0.0" ixz="0.0" iyy="0.000001" iyz="0.0" izz="0.000001"/>
    </inertial>
  </link>
  <!-- [m] -->
  <!-- measured -->
  <!-- joint HFE thigh -->
  <joint name="LH_THIGH_LH_thigh_fixed_A" type="fixed">
    <parent link="LH_THIGH_A"/>
    <child link="LH_thigh_fixed_A"/>
    <origin rpy="0 0 -1.5707963267948966" xyz="0 0 0"/>
  </joint>
  <!-- Thigh link -->
  <link name="LH_thigh_fixed_A">
    <visual>
      <origin rpy="0 0 0.0" xyz="0 0 0"/>
      <geometry>
        <mesh filename="../meshes/thigh_3_1_1_mesh.dae" scale="1.0 1.0     1.0"/>
      </geometry>
    </visual>
    <!-- Thigh collision -->
    <collision>
      <origin rpy="1.5707963267948966 0 0" xyz="0 0.04 0"/>
      <geometry>
        <cylinder length="0.08" radius="0.065"/>
      </geometry>
    </collision>
    <collision>
      <origin rpy="0 0 0" xyz="0 0.03 -0.1413135"/>
      <geometry>
        <box size="0.07500000000000001 0.06 0.282627"/>
      </geometry>
    </collision>
    <inertial>
      <origin rpy="0 0 0" xyz="-0.0 0.018 -0.169"/>
      <mass value="1.03"/>
      <inertia ixx="0.018644469" ixy="-5.2e-08" ixz="-1.0157e-05" iyy="0.019312599" iyz="0.002520077" izz="0.002838361"/>
    </inertial>
  </link>
  <!-- [rad] -->
  <!-- joint thigh KFE -->
  <joint name="LH_thigh_fixed_LH_KFE_A" type="fixed">
    <parent link="LH_thigh_fixed_A"/>
    <child link="LH_KFE_A"/>
    <origin rpy="0 0 1.5707963267948966" xyz="-0.0 0.1003 -0.285"/>
  </joint>
  <!-- [m] -->
  <!-- [A] -->
  <!-- Drive link -->
  <link name="LH_KFE_A">
    <visual>
      <origin rpy="0 0 0" xyz="0 0 0"/>
      <geometry>
        <mesh filename="../meshes/drive_3_0_2_mesh.dae" scale="1.0 1.0     1.0"/>
      </geometry>
    </visual>
    <collision>
      <origin rpy="0 1.5707963267948966 0" xyz="-0.07 0 0"/>
      <geometry>
        <cylinder length="0.14" radius="0.05"/>
      </geometry>
    </collision>
    <inertial>
      <origin rpy="0 0 0" xyz="-0.063 7e-05 0.00046"/>
      <mass value="2.04"/>
      <inertia ixx="0.001053013" ixy="4.527e-05" ixz="8.855e-05" iyy="0.001805509" iyz="9.909e-05" izz="0.001765827"/>
    </inertial>
  </link>
  <!-- joint Drive output -->
  <joint name="LH_KFE_A" type="revolute">
    <parent link="LH_KFE_A"/>
    <child link="LH_SHANK_A"/>
    <origin rpy="0 0 0" xyz="0 0 0"/>
    <axis xyz="1 0 0"/>
    <limit command_effort="80.0" current="32.0" effort="80.0" gear_velocity="7.5" lower="-9.42477796076938" upper="9.42477796076938" velocity="7.5"/>
    <dynamics damping="0.0" friction="0.0"/>
  </joint>
  <!-- Drive output link -->
  <link name="LH_SHANK_A">
    <inertial>
      <origin rpy="0 0 0" xyz="0 0 0"/>
      <mass value="0.001"/>
      <inertia ixx="0.000001" ixy="0.0" ixz="0.0" iyy="0.000001" iyz="0.0" izz="0.000001"/>
    </inertial>
  </link>
  <!-- [m] -->
  <!-- measured -->
  <!-- joint KFE shank -->
  <joint name="LH_shank_LH_shank_fixed_A" type="fixed">
    <parent link="LH_SHANK_A"/>
    <child link="LH_shank_fixed_A"/>
    <origin rpy="0 0 -1.5707963267948966" xyz="0 0 0"/>
  </joint>
  <!-- Shank link -->
  <link name="LH_shank_fixed_A">
    <visual>
      <origin rpy="0 0 -3.141592653589793" xyz="0 0 0"/>
      <geometry>
        <mesh filename="../meshes/shank_3_1_1_mesh_mirrored.dae" scale="1.0 1.0     1.0"/>
      </geometry>
    </visual>
    <!-- Shank collision -->
    <collision>
      <origin rpy="1.5707963267948966 0 0" xyz="0 0.02 0"/>
      <geometry>
        <cylinder length="0.04" radius="0.06"/>
      </geometry>
    </collision>
    <collision>
      <origin rpy="1.5707963267948966 0 0" xyz="-0.057499 0.02 0"/>
      <geometry>
        <box size="0.114998 0.0675 0.04"/>
      </geometry>
    </collision>
    <inertial>
      <origin rpy="0 0 0" xyz="-0.03463 0.00688 0.00098"/>
      <mass value="0.33742"/>
      <inertia ixx="0.00032748005" ixy="-2.142561e-05" ixz="-1.33942e-05" iyy="0.00110974122" iyz="7.601e-08" izz="0.00089388521"/>
    </inertial>
  </link>
  <!-- Leg configurations: xx (knees bent inwards), xo (knees bent backwards) -->
  <!-- joint shank foot -->
  <joint name="LH_shank_fixed_LH_FOOT_A" type="fixed">
    <parent link="LH_shank_fixed_A"/>
    <child link="LH_FOOT_A"/>
    <origin rpy="0 0 0" xyz="-0.08795 0.01305 -0.33797"/>
  </joint>
  <!-- Foot link -->
  <link name="LH_FOOT_A">
    <visual>
      <origin rpy="0 0 -2.356194490192345" xyz="0 0 0"/>
      <geometry>
        <mesh filename="../meshes/foot_3_1_1_mesh.dae" scale="1.0 1.0     1.0"/>
      </geometry>
    </visual>
    <!-- Adapter collision -->
    <collision>
      <origin rpy="0 0 0" xyz="0 0 0.168985"/>
      <geometry>
        <cylinder length="0.282504" radius="0.0175"/>
      </geometry>
    </collision>
    <!-- Foot collision -->
    <collision>
      <origin xyz="0 0 0.0225"/>
      <geometry>
        <sphere radius="0.03"/>
      </geometry>
    </collision>
    <inertial>
      <origin rpy="0 0 0" xyz="-0.00948 -0.00948 0.1468"/>
      <mass value="0.25"/>
      <inertia ixx="0.00317174097" ixy="-2.63048e-06" ixz="-6.815581e-05" iyy="0.00317174092" iyz="6.815583e-05" izz="8.319196e-05"/>
    </inertial>
  </link>
  <!-- Gazebo customization -->
  <gazebo reference="LH_FOOT_A">
    <kp>1000000.0</kp>
    <kd>100.0</kd>
    <mu1>0.8</mu1>
    <mu2>0.8</mu2>
  </gazebo>
  <!-- [rad] -->
  <!-- [rad] -->
  <!-- joint base HAA -->
  <joint name="base_RH_HAA_A" type="fixed">
    <parent link="base_A"/>
    <child link="RH_HAA_A"/>
    <origin rpy="2.6179938779914944 0 -3.141592653589793" xyz="-0.2999 -0.104 0.0"/>
  </joint>
  <!-- [m] -->
  <!-- [A] -->
  <!-- Drive link -->
  <link name="RH_HAA_A">
    <visual>
      <origin rpy="0 0 0" xyz="0 0 0"/>
      <geometry>
        <mesh filename="../meshes/drive_3_0_2_mesh.dae" scale="1.0 1.0     1.0"/>
      </geometry>
    </visual>
    <inertial>
      <origin rpy="0 0 0" xyz="-0.063 7e-05 0.00046"/>
      <mass value="2.04"/>
      <inertia ixx="0.001053013" ixy="4.527e-05" ixz="8.855e-05" iyy="0.001805509" iyz="9.909e-05" izz="0.001765827"/>
    </inertial>
  </link>
  <!-- joint Drive output -->
  <joint name="RH_HAA_A" type="revolute">
    <parent link="RH_HAA_A"/>
    <child link="RH_HIP_A"/>
    <origin rpy="0 0 0" xyz="0 0 0"/>
    <axis xyz="-1 0 0"/>
    <limit command_effort="80.0" current="32.0" effort="80.0" gear_velocity="7.5" lower="-0.49" upper="0.72" velocity="7.5"/>
    <dynamics damping="0.0" friction="0.0"/>
  </joint>
  <!-- Drive output link -->
  <link name="RH_HIP_A">
    <inertial>
      <origin rpy="0 0 0" xyz="0 0 0"/>
      <mass value="0.001"/>
      <inertia ixx="0.000001" ixy="0.0" ixz="0.0" iyy="0.000001" iyz="0.0" izz="0.000001"/>
    </inertial>
  </link>
  <!-- [kg * m^2] -->
  <!-- joint HAA hip -->
  <joint name="RH_HIP_RH_hip_fixed_A" type="fixed">
    <parent link="RH_HIP_A"/>
    <child link="RH_hip_fixed_A"/>
    <origin rpy="2.6179938779914944 0 -3.141592653589793" xyz="0 0 0"/>
  </joint>
  <!-- Hip link -->
  <link name="RH_hip_fixed_A">
    <visual>
      <origin rpy="0 0 -3.141592653589793" xyz="0 0 0"/>
      <geometry>
        <mesh filename="../meshes/hip_3_1_1_mesh.dae" scale="1.0 1.0     1.0"/>
      </geometry>
    </visual>
    <inertial>
      <origin rpy="0 0 0" xyz="-0.048 -0.008 -0.003"/>
      <mass value="0.74"/>
      <inertia ixx="0.001393106" ixy="8.4012e-05" ixz="-2.3378e-05" iyy="0.003798579" iyz="-7.1319e-05" izz="0.003897509"/>
    </inertial>
  </link>
  <!-- [rad] -->
  <!-- joint hip HFE -->
  <joint name="RH_hip_fixed_RH_HFE_A" type="fixed">
    <parent link="RH_hip_fixed_A"/>
    <child link="RH_HFE_A"/>
    <origin rpy="0 0 -1.5707963267948966" xyz="-0.0599 -0.08381 0.0"/>
  </joint>
  <!-- [m] -->
  <!-- [A] -->
  <!-- Drive link -->
  <link name="RH_HFE_A">
    <visual>
      <origin rpy="0 0 0" xyz="0 0 0"/>
      <geometry>
        <mesh filename="../meshes/drive_3_0_2_mesh.dae" scale="1.0 1.0     1.0"/>
      </geometry>
    </visual>
    <collision>
      <origin rpy="0 1.5707963267948966 0" xyz="-0.07 0 0"/>
      <geometry>
        <cylinder length="0.14" radius="0.05"/>
      </geometry>
    </collision>
    <inertial>
      <origin rpy="0 0 0" xyz="-0.063 7e-05 0.00046"/>
      <mass value="2.04"/>
      <inertia ixx="0.001053013" ixy="4.527e-05" ixz="8.855e-05" iyy="0.001805509" iyz="9.909e-05" izz="0.001765827"/>
    </inertial>
  </link>
  <!-- joint Drive output -->
  <joint name="RH_HFE_A" type="revolute">
    <parent link="RH_HFE_A"/>
    <child link="RH_THIGH_A"/>
    <origin rpy="0 0 0" xyz="0 0 0"/>
    <axis xyz="-1 0 0"/>
    <limit command_effort="80.0" current="32.0" effort="80.0" gear_velocity="7.5" lower="-9.42477796076938" upper="9.42477796076938" velocity="7.5"/>
    <dynamics damping="0.0" friction="0.0"/>
  </joint>
  <!-- Drive output link -->
  <link name="RH_THIGH_A">
    <inertial>
      <origin rpy="0 0 0" xyz="0 0 0"/>
      <mass value="0.001"/>
      <inertia ixx="0.000001" ixy="0.0" ixz="0.0" iyy="0.000001" iyz="0.0" izz="0.000001"/>
    </inertial>
  </link>
  <!-- [m] -->
  <!-- measured -->
  <!-- joint HFE thigh -->
  <joint name="RH_THIGH_RH_thigh_fixed_A" type="fixed">
    <parent link="RH_THIGH_A"/>
    <child link="RH_thigh_fixed_A"/>
    <origin rpy="0 0 1.5707963267948966" xyz="0 0 0"/>
  </joint>
  <!-- Thigh link -->
  <link name="RH_thigh_fixed_A">
    <visual>
      <origin rpy="0 0 -3.141592653589793" xyz="0 0 0"/>
      <geometry>
        <mesh filename="../meshes/thigh_3_1_1_mesh.dae" scale="1.0 1.0     1.0"/>
      </geometry>
    </visual>
    <!-- Thigh collision -->
    <collision>
      <origin rpy="1.5707963267948966 0 0" xyz="0 -0.04 0"/>
      <geometry>
        <cylinder length="0.08" radius="0.065"/>
      </geometry>
    </collision>
    <collision>
      <origin rpy="0 0 0" xyz="0 -0.03 -0.1413135"/>
      <geometry>
        <box size="0.07500000000000001 0.06 0.282627"/>
      </geometry>
    </collision>
    <inertial>
      <origin rpy="0 0 0" xyz="-0.0 -0.018 -0.169"/>
      <mass value="1.03"/>
      <inertia ixx="0.018644469" ixy="5.2e-08" ixz="-1.0157e-05" iyy="0.019312599" iyz="-0.002520077" izz="0.002838361"/>
    </inertial>
  </link>
  <!-- [rad] -->
  <!-- joint thigh KFE -->
  <joint name="RH_thigh_fixed_RH_KFE_A" type="fixed">
    <parent link="RH_thigh_fixed_A"/>
    <child link="RH_KFE_A"/>
    <origin rpy="0 0 -1.5707963267948966" xyz="-0.0 -0.1003 -0.285"/>
  </joint>
  <!-- [m] -->
  <!-- [A] -->
  <!-- Drive link -->
  <link name="RH_KFE_A">
    <visual>
      <origin rpy="0 0 0" xyz="0 0 0"/>
      <geometry>
        <mesh filename="../meshes/drive_3_0_2_mesh.dae" scale="1.0 1.0     1.0"/>
      </geometry>
    </visual>
    <collision>
      <origin rpy="0 1.5707963267948966 0" xyz="-0.07 0 0"/>
      <geometry>
        <cylinder length="0.14" radius="0.05"/>
      </geometry>
    </collision>
    <inertial>
      <origin rpy="0 0 0" xyz="-0.063 7e-05 0.00046"/>
      <mass value="2.04"/>
      <inertia ixx="0.001053013" ixy="4.527e-05" ixz="8.855e-05" iyy="0.001805509" iyz="9.909e-05" izz="0.001765827"/>
    </inertial>
  </link>
  <!-- joint Drive output -->
  <joint name="RH_KFE_A" type="revolute">
    <parent link="RH_KFE_A"/>
    <child link="RH_SHANK_A"/>
    <origin rpy="0 0 0" xyz="0 0 0"/>
    <axis xyz="-1 0 0"/>
    <limit command_effort="80.0" current="32.0" effort="80.0" gear_velocity="7.5" lower="-9.42477796076938" upper="9.42477796076938" velocity="7.5"/>
    <dynamics damping="0.0" friction="0.0"/>
  </joint>
  <!-- Drive output link -->
  <link name="RH_SHANK_A">
    <inertial>
      <origin rpy="0 0 0" xyz="0 0 0"/>
      <mass value="0.001"/>
      <inertia ixx="0.000001" ixy="0.0" ixz="0.0" iyy="0.000001" iyz="0.0" izz="0.000001"/>
    </inertial>
  </link>
  <!-- [m] -->
  <!-- measured -->
  <!-- joint KFE shank -->
  <joint name="RH_shank_RH_shank_fixed_A" type="fixed">
    <parent link="RH_SHANK_A"/>
    <child link="RH_shank_fixed_A"/>
    <origin rpy="0 0 1.5707963267948966" xyz="0 0 0"/>
  </joint>
  <!-- Shank link -->
  <link name="RH_shank_fixed_A">
    <visual>
      <origin rpy="0 0 -3.141592653589793" xyz="0 0 0"/>
      <geometry>
        <mesh filename="../meshes/shank_3_1_1_mesh.dae" scale="1.0 1.0     1.0"/>
      </geometry>
    </visual>
    <!-- Shank collision -->
    <collision>
      <origin rpy="1.5707963267948966 0 0" xyz="0 -0.02 0"/>
      <geometry>
        <cylinder length="0.04" radius="0.06"/>
      </geometry>
    </collision>
    <collision>
      <origin rpy="1.5707963267948966 0 0" xyz="-0.057499 -0.02 0"/>
      <geometry>
        <box size="0.114998 0.0675 0.04"/>
      </geometry>
    </collision>
    <inertial>
      <origin rpy="0 0 0" xyz="-0.03463 -0.00688 0.00098"/>
      <mass value="0.33742"/>
      <inertia ixx="0.00032748005" ixy="2.142561e-05" ixz="-1.33942e-05" iyy="0.00110974122" iyz="-7.601e-08" izz="0.00089388521"/>
    </inertial>
  </link>
  <!-- Leg configurations: xx (knees bent inwards), xo (knees bent backwards) -->
  <!-- joint shank foot -->
  <joint name="RH_shank_fixed_RH_FOOT_A" type="fixed">
    <parent link="RH_shank_fixed_A"/>
    <child link="RH_FOOT_A"/>
    <origin rpy="0 0 0" xyz="-0.08795 -0.01305 -0.33797"/>
  </joint>
  <!-- Foot link -->
  <link name="RH_FOOT_A">
    <visual>
      <origin rpy="0 0 -3.9269908169872414" xyz="0 0 0"/>
      <geometry>
        <mesh filename="../meshes/foot_3_1_1_mesh.dae" scale="1.0 1.0     1.0"/>
      </geometry>
    </visual>
    <!-- Adapter collision -->
    <collision>
      <origin rpy="0 0 0" xyz="0 0 0.168985"/>
      <geometry>
        <cylinder length="0.282504" radius="0.0175"/>
      </geometry>
    </collision>
    <!-- Foot collision -->
    <collision>
      <origin xyz="0 0 0.0225"/>
      <geometry>
        <sphere radius="0.03"/>
      </geometry>
    </collision>
    <inertial>
      <origin rpy="0 0 0" xyz="-0.00948 0.00948 0.1468"/>
      <mass value="0.25"/>
      <inertia ixx="0.00317174097" ixy="2.63048e-06" ixz="-6.815581e-05" iyy="0.00317174092" iyz="-6.815583e-05" izz="8.319196e-05"/>
    </inertial>
  </link>
  <!-- Gazebo customization -->
  <gazebo reference="RH_FOOT_A">
    <kp>1000000.0</kp>
    <kd>100.0</kd>
    <mu1>0.8</mu1>
    <mu2>0.8</mu2>
  </gazebo>
  <!-- [kg * m^2] -->
  <!-- Fixed joint base hatch -->
  <joint name="base_hatch_A" type="fixed">
    <parent link="base_A"/>
    <child link="hatch_A"/>
    <origin rpy="0 0 0" xyz="0.0 0.0 0.0"/>
  </joint>
  <!-- Hatch link -->
  <link name="hatch_A">
    <visual>
      <origin rpy="0 0 0" xyz="0.116 0 0.073"/>
      <geometry>
        <mesh filename="../meshes/hatch_3_1_1_mesh.dae" scale="1.0 1.0 1.0"/>
      </geometry>
    </visual>
    <inertial>
      <origin rpy="0 0 0" xyz="0.116 0.0 0.0758"/>
      <mass value="0.142"/>
      <inertia ixx="0.001" ixy="0.001" ixz="0.001" iyy="0.001" iyz="0.001" izz="0.001"/>
    </inertial>
  </link>
</robot>
